Workbook

Sheet 프로젝트WBS
B1: 모델하우스 컨피규레이터 | K1: 실적기준일 | L1: 46308 | M1: ="실적 미입력 "&(83-COUNT(T6:T88))&" / 83건" -> 실적 미입력 0 / 83건 | T1: SPI | U1: =IF(OR(U5="",S5=0),"",U5/S5) -> 0.85018293 | V1: =IF(U1="","미확인",IF(U1<0.75,"위험",IF(U1<0.85,"경고",IF(U1<0.95,"주의","양호")))) -> 주의
B3: 단계 | F3: TASK | H3: 담당 | J3: 산출물 / 완료 기준 | K3: 계획 시작일 | L3: 예상 완료일 | M3: 실제 시작일 | N3: 실제 완료(예정)일 | O3: 계획 기간 | P3: 실제 기간 | Q3: 계획 진행 | R3: 실제 진행 | S3: 계획 완료율 | T3: 작업 완료율 | U3: 프로젝트 실적 | W3: 일정 | AF3: 실적 입력
H4: 주담당 | I4: 검토 | U4: 진척률 | V4: 차이(%p) | W4: 2026년 10월 | AF4: 작업 상태 | AG4: 전체 작업량 | AH4: 완료 작업량
B5: 번호 | C5: 가중치 | D5: 수행단계 | K5: =MIN(K6:K88) -> 46301 | L5: =MAX(L6:L88) -> 46309 | M5: =IF(COUNT(M6:M88)=0,"",MIN(M6:M88)) -> 46301 | N5: =IF(COUNT(N6:N88)=0,"",MAX(N6:N88)) -> 46308 | O5: =SUM(O6:O88) -> 83 | P5: =IF(COUNT(P6:P88)=0,"",SUM(P6:P88)) -> 78 | Q5: =SUM(Q6:Q88) -> 69 | R5: =IF(COUNT(R6:R88)=0,"",SUM(R6:R88)) -> 84 | S5: =AVERAGE(S6:S10)*C6+AVERAGE(S11:S22)*C11+AVERAGE(S23:S39)*C23+AVERAGE(S40:S63)*C40+AVERAGE(S64:S74)*C64+AVERAGE(S75:S88)*C75 -> 0.81818182 | T5: =IF(COUNT(T6:T88)<83,"",AVERAGE(T6:T88)) -> 0.73192771 | U5: =IF(COUNT(T6:T88)<83,"",AVERAGE(T6:T10)*C6+AVERAGE(T11:T22)*C11+AVERAGE(T23:T39)*C23+AVERAGE(T40:T63)*C40+AVERAGE(T64:T74)*C64+AVERAGE(T75:T88)*C75) -> 0.69560421 | V5: =IF(U5="","",U5-S5) -> -0.12257761 | W5: 46301 | X5: 46302 | Y5: 46303 | Z5: 46304 | AA5: 46305 | AB5: 46306 | AC5: 46307 | AD5: 46308 | AE5: 46309
B6: 1 | C6: 0.090909091 | D6: 기획·설계 | F6: 1.01 SRS 범위 및 Must 확정 (v2.7: 13개) | H6: 권오민 | I6: 김찬중 | J6: 전체 삭제 요구사항 제외, FR-29 하위 7개와 부모 중복 집계 없음 v2.7: 강사 피드백(정지·일시정지·옵션 초기화) 반영 | K6: 46301 | L6: 46301 | M6: 46301 | N6: 46307 | O6: =IF(OR(K6="",L6=""),"",IF(L6<K6,"날짜 확인",NETWORKDAYS(K6,L6,휴일!$A$2:$A$2))) -> 1 | P6: =IF(OR(M6="",N6=""),"",IF(N6<M6,"날짜 확인",NETWORKDAYS(M6,N6,휴일!$A$2:$A$2))) -> 4 | Q6: =IF(O6="","",IF($L$1<K6,0,NETWORKDAYS(K6,MIN($L$1,L6),휴일!$A$2:$A$2))) -> 1 | R6: =IF(M6="","",IF($L$1<M6,0,NETWORKDAYS(M6,IF(N6="",$L$1,MIN($L$1,N6)),휴일!$A$2:$A$2))) -> 4 | S6: =IF(O6="","",IF(O6=0,0,Q6/O6)) -> 1 | T6: =IF(OR(AND(AG6<>"",OR(NOT(ISNUMBER(AG6)),AG6<=0)),AND(AH6<>"",OR(NOT(ISNUMBER(AH6)),AH6<0)),AND(ISNUMBER(AG6),ISNUMBER(AH6),AH6>AG6)),"수량 확인",IF(AF6="완료",1,IF(AF6="미착수",0,IF(AND(ISNUMBER(AG6),ISNUMBER(AH6)),AH6/AG6,"")))) -> 1 | U6: =IF(T6="","",T6) -> 1 | V6: =IF(OR(U6="",S6=""),"",U6-S6) -> 0 | W6: =IF(AND(ISNUMBER($M6),W$5>=$M6,W$5<=IF($N6="",$L$1,$N6),WEEKDAY(W$5,2)<6,COUNTIF(휴일!$A$2:$A$2,W$5)=0),2,IF(AND(ISNUMBER($K6),W$5>=$K6,W$5<=$L6,WEEKDAY(W$5,2)<6,COUNTIF(휴일!$A$2:$A$2,W$5)=0),1,"")) -> 2 | X6: =IF(AND(ISNUMBER($M6),X$5>=$M6,X$5<=IF($N6="",$L$1,$N6),WEEKDAY(X$5,2)<6,COUNTIF(휴일!$A$2:$A$2,X$5)=0),2,IF(AND(ISNUMBER($K6),X$5>=$K6,X$5<=$L6,WEEKDAY(X$5,2)<6,COUNTIF(휴일!$A$2:$A$2,X$5)=0),1,"")) -> 2 | Y6: =IF(AND(ISNUMBER($M6),Y$5>=$M6,Y$5<=IF($N6="",$L$1,$N6),WEEKDAY(Y$5,2)<6,COUNTIF(휴일!$A$2:$A$2,Y$5)=0),2,IF(AND(ISNUMBER($K6),Y$5>=$K6,Y$5<=$L6,WEEKDAY(Y$5,2)<6,COUNTIF(휴일!$A$2:$A$2,Y$5)=0),1,"")) -> 2 | Z6: =IF(AND(ISNUMBER($M6),Z$5>=$M6,Z$5<=IF($N6="",$L$1,$N6),WEEKDAY(Z$5,2)<6,COUNTIF(휴일!$A$2:$A$2,Z$5)=0),2,IF(AND(ISNUMBER($K6),Z$5>=$K6,Z$5<=$L6,WEEKDAY(Z$5,2)<6,COUNTIF(휴일!$A$2:$A$2,Z$5)=0),1,"")) | AA6: =IF(AND(ISNUMBER($M6),AA$5>=$M6,AA$5<=IF($N6="",$L$1,$N6),WEEKDAY(AA$5,2)<6,COUNTIF(휴일!$A$2:$A$2,AA$5)=0),2,IF(AND(ISNUMBER($K6),AA$5>=$K6,AA$5<=$L6,WEEKDAY(AA$5,2)<6,COUNTIF(휴일!$A$2:$A$2,AA$5)=0),1,"")) | AB6: =IF(AND(ISNUMBER($M6),AB$5>=$M6,AB$5<=IF($N6="",$L$1,$N6),WEEKDAY(AB$5,2)<6,COUNTIF(휴일!$A$2:$A$2,AB$5)=0),2,IF(AND(ISNUMBER($K6),AB$5>=$K6,AB$5<=$L6,WEEKDAY(AB$5,2)<6,COUNTIF(휴일!$A$2:$A$2,AB$5)=0),1,"")) | AC6: =IF(AND(ISNUMBER($M6),AC$5>=$M6,AC$5<=IF($N6="",$L$1,$N6),WEEKDAY(AC$5,2)<6,COUNTIF(휴일!$A$2:$A$2,AC$5)=0),2,IF(AND(ISNUMBER($K6),AC$5>=$K6,AC$5<=$L6,WEEKDAY(AC$5,2)<6,COUNTIF(휴일!$A$2:$A$2,AC$5)=0),1,"")) -> 2 | AD6: =IF(AND(ISNUMBER($M6),AD$5>=$M6,AD$5<=IF($N6="",$L$1,$N6),WEEKDAY(AD$5,2)<6,COUNTIF(휴일!$A$2:$A$2,AD$5)=0),2,IF(AND(ISNUMBER($K6),AD$5>=$K6,AD$5<=$L6,WEEKDAY(AD$5,2)<6,COUNTIF(휴일!$A$2:$A$2,AD$5)=0),1,"")) | AE6: =IF(AND(ISNUMBER($M6),AE$5>=$M6,AE$5<=IF($N6="",$L$1,$N6),WEEKDAY(AE$5,2)<6,COUNTIF(휴일!$A$2:$A$2,AE$5)=0),2,IF(AND(ISNUMBER($K6),AE$5>=$K6,AE$5<=$L6,WEEKDAY(AE$5,2)<6,COUNTIF(휴일!$A$2:$A$2,AE$5)=0),1,"")) | AF6: 완료
F7: 1.02 이벤트·상태·장치 인터페이스 설계 | H7: 김찬중 | I7: 권오민 | J7: NFR-05/06 HomeEvents, 상태 DTO, 로봇 인터페이스 합의 | K7: 46301 | L7: 46301 | M7: 46301 | N7: 46303 | O7: =IF(OR(K7="",L7=""),"",IF(L7<K7,"날짜 확인",NETWORKDAYS(K7,L7,휴일!$A$2:$A$2))) -> 1 | P7: =IF(OR(M7="",N7=""),"",IF(N7<M7,"날짜 확인",NETWORKDAYS(M7,N7,휴일!$A$2:$A$2))) -> 3 | Q7: =IF(O7="","",IF($L$1<K7,0,NETWORKDAYS(K7,MIN($L$1,L7),휴일!$A$2:$A$2))) -> 1 | R7: =IF(M7="","",IF($L$1<M7,0,NETWORKDAYS(M7,IF(N7="",$L$1,MIN($L$1,N7)),휴일!$A$2:$A$2))) -> 3 | S7: =IF(O7="","",IF(O7=0,0,Q7/O7)) -> 1 | T7: =IF(OR(AND(AG7<>"",OR(NOT(ISNUMBER(AG7)),AG7<=0)),AND(AH7<>"",OR(NOT(ISNUMBER(AH7)),AH7<0)),AND(ISNUMBER(AG7),ISNUMBER(AH7),AH7>AG7)),"수량 확인",IF(AF7="완료",1,IF(AF7="미착수",0,IF(AND(ISNUMBER(AG7),ISNUMBER(AH7)),AH7/AG7,"")))) -> 1 | U7: =IF(T7="","",T7) -> 1 | V7: =IF(OR(U7="",S7=""),"",U7-S7) -> 0 | W7: =IF(AND(ISNUMBER($M7),W$5>=$M7,W$5<=IF($N7="",$L$1,$N7),WEEKDAY(W$5,2)<6,COUNTIF(휴일!$A$2:$A$2,W$5)=0),2,IF(AND(ISNUMBER($K7),W$5>=$K7,W$5<=$L7,WEEKDAY(W$5,2)<6,COUNTIF(휴일!$A$2:$A$2,W$5)=0),1,"")) -> 2 | X7: =IF(AND(ISNUMBER($M7),X$5>=$M7,X$5<=IF($N7="",$L$1,$N7),WEEKDAY(X$5,2)<6,COUNTIF(휴일!$A$2:$A$2,X$5)=0),2,IF(AND(ISNUMBER($K7),X$5>=$K7,X$5<=$L7,WEEKDAY(X$5,2)<6,COUNTIF(휴일!$A$2:$A$2,X$5)=0),1,"")) -> 2 | Y7: =IF(AND(ISNUMBER($M7),Y$5>=$M7,Y$5<=IF($N7="",$L$1,$N7),WEEKDAY(Y$5,2)<6,COUNTIF(휴일!$A$2:$A$2,Y$5)=0),2,IF(AND(ISNUMBER($K7),Y$5>=$K7,Y$5<=$L7,WEEKDAY(Y$5,2)<6,COUNTIF(휴일!$A$2:$A$2,Y$5)=0),1,"")) -> 2 | Z7: =IF(AND(ISNUMBER($M7),Z$5>=$M7,Z$5<=IF($N7="",$L$1,$N7),WEEKDAY(Z$5,2)<6,COUNTIF(휴일!$A$2:$A$2,Z$5)=0),2,IF(AND(ISNUMBER($K7),Z$5>=$K7,Z$5<=$L7,WEEKDAY(Z$5,2)<6,COUNTIF(휴일!$A$2:$A$2,Z$5)=0),1,"")) | AA7: =IF(AND(ISNUMBER($M7),AA$5>=$M7,AA$5<=IF($N7="",$L$1,$N7),WEEKDAY(AA$5,2)<6,COUNTIF(휴일!$A$2:$A$2,AA$5)=0),2,IF(AND(ISNUMBER($K7),AA$5>=$K7,AA$5<=$L7,WEEKDAY(AA$5,2)<6,COUNTIF(휴일!$A$2:$A$2,AA$5)=0),1,"")) | AB7: =IF(AND(ISNUMBER($M7),AB$5>=$M7,AB$5<=IF($N7="",$L$1,$N7),WEEKDAY(AB$5,2)<6,COUNTIF(휴일!$A$2:$A$2,AB$5)=0),2,IF(AND(ISNUMBER($K7),AB$5>=$K7,AB$5<=$L7,WEEKDAY(AB$5,2)<6,COUNTIF(휴일!$A$2:$A$2,AB$5)=0),1,"")) | AC7: =IF(AND(ISNUMBER($M7),AC$5>=$M7,AC$5<=IF($N7="",$L$1,$N7),WEEKDAY(AC$5,2)<6,COUNTIF(휴일!$A$2:$A$2,AC$5)=0),2,IF(AND(ISNUMBER($K7),AC$5>=$K7,AC$5<=$L7,WEEKDAY(AC$5,2)<6,COUNTIF(휴일!$A$2:$A$2,AC$5)=0),1,"")) | AD7: =IF(AND(ISNUMBER($M7),AD$5>=$M7,AD$5<=IF($N7="",$L$1,$N7),WEEKDAY(AD$5,2)<6,COUNTIF(휴일!$A$2:$A$2,AD$5)=0),2,IF(AND(ISNUMBER($K7),AD$5>=$K7,AD$5<=$L7,WEEKDAY(AD$5,2)<6,COUNTIF(휴일!$A$2:$A$2,AD$5)=0),1,"")) | AE7: =IF(AND(ISNUMBER($M7),AE$5>=$M7,AE$5<=IF($N7="",$L$1,$N7),WEEKDAY(AE$5,2)<6,COUNTIF(휴일!$A$2:$A$2,AE$5)=0),2,IF(AND(ISNUMBER($K7),AE$5>=$K7,AE$5<=$L7,WEEKDAY(AE$5,2)<6,COUNTIF(휴일!$A$2:$A$2,AE$5)=0),1,"")) | AF7: 완료
F8: 1.03 화면 흐름·메뉴·시연 동선 설계 | H8: 권오민 | I8: 김찬중 | J8: FR-01/11/34 현관부터 커피·옵션·시간대까지 동선 확정 | K8: 46301 | L8: 46301 | M8: 46301 | N8: 46302 | O8: =IF(OR(K8="",L8=""),"",IF(L8<K8,"날짜 확인",NETWORKDAYS(K8,L8,휴일!$A$2:$A$2))) -> 1 | P8: =IF(OR(M8="",N8=""),"",IF(N8<M8,"날짜 확인",NETWORKDAYS(M8,N8,휴일!$A$2:$A$2))) -> 2 | Q8: =IF(O8="","",IF($L$1<K8,0,NETWORKDAYS(K8,MIN($L$1,L8),휴일!$A$2:$A$2))) -> 1 | R8: =IF(M8="","",IF($L$1<M8,0,NETWORKDAYS(M8,IF(N8="",$L$1,MIN($L$1,N8)),휴일!$A$2:$A$2))) -> 2 | S8: =IF(O8="","",IF(O8=0,0,Q8/O8)) -> 1 | T8: =IF(OR(AND(AG8<>"",OR(NOT(ISNUMBER(AG8)),AG8<=0)),AND(AH8<>"",OR(NOT(ISNUMBER(AH8)),AH8<0)),AND(ISNUMBER(AG8),ISNUMBER(AH8),AH8>AG8)),"수량 확인",IF(AF8="완료",1,IF(AF8="미착수",0,IF(AND(ISNUMBER(AG8),ISNUMBER(AH8)),AH8/AG8,"")))) -> 1 | U8: =IF(T8="","",T8) -> 1 | V8: =IF(OR(U8="",S8=""),"",U8-S8) -> 0 | W8: =IF(AND(ISNUMBER($M8),W$5>=$M8,W$5<=IF($N8="",$L$1,$N8),WEEKDAY(W$5,2)<6,COUNTIF(휴일!$A$2:$A$2,W$5)=0),2,IF(AND(ISNUMBER($K8),W$5>=$K8,W$5<=$L8,WEEKDAY(W$5,2)<6,COUNTIF(휴일!$A$2:$A$2,W$5)=0),1,"")) -> 2 | X8: =IF(AND(ISNUMBER($M8),X$5>=$M8,X$5<=IF($N8="",$L$1,$N8),WEEKDAY(X$5,2)<6,COUNTIF(휴일!$A$2:$A$2,X$5)=0),2,IF(AND(ISNUMBER($K8),X$5>=$K8,X$5<=$L8,WEEKDAY(X$5,2)<6,COUNTIF(휴일!$A$2:$A$2,X$5)=0),1,"")) -> 2 | Y8: =IF(AND(ISNUMBER($M8),Y$5>=$M8,Y$5<=IF($N8="",$L$1,$N8),WEEKDAY(Y$5,2)<6,COUNTIF(휴일!$A$2:$A$2,Y$5)=0),2,IF(AND(ISNUMBER($K8),Y$5>=$K8,Y$5<=$L8,WEEKDAY(Y$5,2)<6,COUNTIF(휴일!$A$2:$A$2,Y$5)=0),1,"")) | Z8: =IF(AND(ISNUMBER($M8),Z$5>=$M8,Z$5<=IF($N8="",$L$1,$N8),WEEKDAY(Z$5,2)<6,COUNTIF(휴일!$A$2:$A$2,Z$5)=0),2,IF(AND(ISNUMBER($K8),Z$5>=$K8,Z$5<=$L8,WEEKDAY(Z$5,2)<6,COUNTIF(휴일!$A$2:$A$2,Z$5)=0),1,"")) | AA8: =IF(AND(ISNUMBER($M8),AA$5>=$M8,AA$5<=IF($N8="",$L$1,$N8),WEEKDAY(AA$5,2)<6,COUNTIF(휴일!$A$2:$A$2,AA$5)=0),2,IF(AND(ISNUMBER($K8),AA$5>=$K8,AA$5<=$L8,WEEKDAY(AA$5,2)<6,COUNTIF(휴일!$A$2:$A$2,AA$5)=0),1,"")) | AB8: =IF(AND(ISNUMBER($M8),AB$5>=$M8,AB$5<=IF($N8="",$L$1,$N8),WEEKDAY(AB$5,2)<6,COUNTIF(휴일!$A$2:$A$2,AB$5)=0),2,IF(AND(ISNUMBER($K8),AB$5>=$K8,AB$5<=$L8,WEEKDAY(AB$5,2)<6,COUNTIF(휴일!$A$2:$A$2,AB$5)=0),1,"")) | AC8: =IF(AND(ISNUMBER($M8),AC$5>=$M8,AC$5<=IF($N8="",$L$1,$N8),WEEKDAY(AC$5,2)<6,COUNTIF(휴일!$A$2:$A$2,AC$5)=0),2,IF(AND(ISNUMBER($K8),AC$5>=$K8,AC$5<=$L8,WEEKDAY(AC$5,2)<6,COUNTIF(휴일!$A$2:$A$2,AC$5)=0),1,"")) | AD8: =IF(AND(ISNUMBER($M8),AD$5>=$M8,AD$5<=IF($N8="",$L$1,$N8),WEEKDAY(AD$5,2)<6,COUNTIF(휴일!$A$2:$A$2,AD$5)=0),2,IF(AND(ISNUMBER($K8),AD$5>=$K8,AD$5<=$L8,WEEKDAY(AD$5,2)<6,COUNTIF(휴일!$A$2:$A$2,AD$5)=0),1,"")) | AE8: =IF(AND(ISNUMBER($M8),AE$5>=$M8,AE$5<=IF($N8="",$L$1,$N8),WEEKDAY(AE$5,2)<6,COUNTIF(휴일!$A$2:$A$2,AE$5)=0),2,IF(AND(ISNUMBER($K8),AE$5>=$K8,AE$5<=$L8,WEEKDAY(AE$5,2)<6,COUNTIF(휴일!$A$2:$A$2,AE$5)=0),1,"")) | AF8: 완료
F9: 1.04 인수 기준 및 테스트 환경 정리 | H9: 김찬중 | I9: 권오민 | J9: 전체 시연 PC 사양·Windows 10/11 확보 여부 기록 | K9: 46301 | L9: 46301 | M9: 46301 | N9: 46302 | O9: =IF(OR(K9="",L9=""),"",IF(L9<K9,"날짜 확인",NETWORKDAYS(K9,L9,휴일!$A$2:$A$2))) -> 1 | P9: =IF(OR(M9="",N9=""),"",IF(N9<M9,"날짜 확인",NETWORKDAYS(M9,N9,휴일!$A$2:$A$2))) -> 2 | Q9: =IF(O9="","",IF($L$1<K9,0,NETWORKDAYS(K9,MIN($L$1,L9),휴일!$A$2:$A$2))) -> 1 | R9: =IF(M9="","",IF($L$1<M9,0,NETWORKDAYS(M9,IF(N9="",$L$1,MIN($L$1,N9)),휴일!$A$2:$A$2))) -> 2 | S9: =IF(O9="","",IF(O9=0,0,Q9/O9)) -> 1 | T9: =IF(OR(AND(AG9<>"",OR(NOT(ISNUMBER(AG9)),AG9<=0)),AND(AH9<>"",OR(NOT(ISNUMBER(AH9)),AH9<0)),AND(ISNUMBER(AG9),ISNUMBER(AH9),AH9>AG9)),"수량 확인",IF(AF9="완료",1,IF(AF9="미착수",0,IF(AND(ISNUMBER(AG9),ISNUMBER(AH9)),AH9/AG9,"")))) -> 1 | U9: =IF(T9="","",T9) -> 1 | V9: =IF(OR(U9="",S9=""),"",U9-S9) -> 0 | W9: =IF(AND(ISNUMBER($M9),W$5>=$M9,W$5<=IF($N9="",$L$1,$N9),WEEKDAY(W$5,2)<6,COUNTIF(휴일!$A$2:$A$2,W$5)=0),2,IF(AND(ISNUMBER($K9),W$5>=$K9,W$5<=$L9,WEEKDAY(W$5,2)<6,COUNTIF(휴일!$A$2:$A$2,W$5)=0),1,"")) -> 2 | X9: =IF(AND(ISNUMBER($M9),X$5>=$M9,X$5<=IF($N9="",$L$1,$N9),WEEKDAY(X$5,2)<6,COUNTIF(휴일!$A$2:$A$2,X$5)=0),2,IF(AND(ISNUMBER($K9),X$5>=$K9,X$5<=$L9,WEEKDAY(X$5,2)<6,COUNTIF(휴일!$A$2:$A$2,X$5)=0),1,"")) -> 2 | Y9: =IF(AND(ISNUMBER($M9),Y$5>=$M9,Y$5<=IF($N9="",$L$1,$N9),WEEKDAY(Y$5,2)<6,COUNTIF(휴일!$A$2:$A$2,Y$5)=0),2,IF(AND(ISNUMBER($K9),Y$5>=$K9,Y$5<=$L9,WEEKDAY(Y$5,2)<6,COUNTIF(휴일!$A$2:$A$2,Y$5)=0),1,"")) | Z9: =IF(AND(ISNUMBER($M9),Z$5>=$M9,Z$5<=IF($N9="",$L$1,$N9),WEEKDAY(Z$5,2)<6,COUNTIF(휴일!$A$2:$A$2,Z$5)=0),2,IF(AND(ISNUMBER($K9),Z$5>=$K9,Z$5<=$L9,WEEKDAY(Z$5,2)<6,COUNTIF(휴일!$A$2:$A$2,Z$5)=0),1,"")) | AA9: =IF(AND(ISNUMBER($M9),AA$5>=$M9,AA$5<=IF($N9="",$L$1,$N9),WEEKDAY(AA$5,2)<6,COUNTIF(휴일!$A$2:$A$2,AA$5)=0),2,IF(AND(ISNUMBER($K9),AA$5>=$K9,AA$5<=$L9,WEEKDAY(AA$5,2)<6,COUNTIF(휴일!$A$2:$A$2,AA$5)=0),1,"")) | AB9: =IF(AND(ISNUMBER($M9),AB$5>=$M9,AB$5<=IF($N9="",$L$1,$N9),WEEKDAY(AB$5,2)<6,COUNTIF(휴일!$A$2:$A$2,AB$5)=0),2,IF(AND(ISNUMBER($K9),AB$5>=$K9,AB$5<=$L9,WEEKDAY(AB$5,2)<6,COUNTIF(휴일!$A$2:$A$2,AB$5)=0),1,"")) | AC9: =IF(AND(ISNUMBER($M9),AC$5>=$M9,AC$5<=IF($N9="",$L$1,$N9),WEEKDAY(AC$5,2)<6,COUNTIF(휴일!$A$2:$A$2,AC$5)=0),2,IF(AND(ISNUMBER($K9),AC$5>=$K9,AC$5<=$L9,WEEKDAY(AC$5,2)<6,COUNTIF(휴일!$A$2:$A$2,AC$5)=0),1,"")) | AD9: =IF(AND(ISNUMBER($M9),AD$5>=$M9,AD$5<=IF($N9="",$L$1,$N9),WEEKDAY(AD$5,2)<6,COUNTIF(휴일!$A$2:$A$2,AD$5)=0),2,IF(AND(ISNUMBER($K9),AD$5>=$K9,AD$5<=$L9,WEEKDAY(AD$5,2)<6,COUNTIF(휴일!$A$2:$A$2,AD$5)=0),1,"")) | AE9: =IF(AND(ISNUMBER($M9),AE$5>=$M9,AE$5<=IF($N9="",$L$1,$N9),WEEKDAY(AE$5,2)<6,COUNTIF(휴일!$A$2:$A$2,AE$5)=0),2,IF(AND(ISNUMBER($K9),AE$5>=$K9,AE$5<=$L9,WEEKDAY(AE$5,2)<6,COUNTIF(휴일!$A$2:$A$2,AE$5)=0),1,"")) | AF9: 완료
F10: 1.05 담당·브랜치·씬 소유권 합의 | H10: 권오민 | I10: 김찬중 | J10: 관리 Main은 권오민만 편집, 로봇은 독립 프리팹으로 전달 | K10: 46301 | L10: 46301 | M10: 46301 | N10: 46302 | O10: =IF(OR(K10="",L10=""),"",IF(L10<K10,"날짜 확인",NETWORKDAYS(K10,L10,휴일!$A$2:$A$2))) -> 1 | P10: =IF(OR(M10="",N10=""),"",IF(N10<M10,"날짜 확인",NETWORKDAYS(M10,N10,휴일!$A$2:$A$2))) -> 2 | Q10: =IF(O10="","",IF($L$1<K10,0,NETWORKDAYS(K10,MIN($L$1,L10),휴일!$A$2:$A$2))) -> 1 | R10: =IF(M10="","",IF($L$1<M10,0,NETWORKDAYS(M10,IF(N10="",$L$1,MIN($L$1,N10)),휴일!$A$2:$A$2))) -> 2 | S10: =IF(O10="","",IF(O10=0,0,Q10/O10)) -> 1 | T10: =IF(OR(AND(AG10<>"",OR(NOT(ISNUMBER(AG10)),AG10<=0)),AND(AH10<>"",OR(NOT(ISNUMBER(AH10)),AH10<0)),AND(ISNUMBER(AG10),ISNUMBER(AH10),AH10>AG10)),"수량 확인",IF(AF10="완료",1,IF(AF10="미착수",0,IF(AND(ISNUMBER(AG10),ISNUMBER(AH10)),AH10/AG10,"")))) -> 1 | U10: =IF(T10="","",T10) -> 1 | V10: =IF(OR(U10="",S10=""),"",U10-S10) -> 0 | W10: =IF(AND(ISNUMBER($M10),W$5>=$M10,W$5<=IF($N10="",$L$1,$N10),WEEKDAY(W$5,2)<6,COUNTIF(휴일!$A$2:$A$2,W$5)=0),2,IF(AND(ISNUMBER($K10),W$5>=$K10,W$5<=$L10,WEEKDAY(W$5,2)<6,COUNTIF(휴일!$A$2:$A$2,W$5)=0),1,"")) -> 2 | X10: =IF(AND(ISNUMBER($M10),X$5>=$M10,X$5<=IF($N10="",$L$1,$N10),WEEKDAY(X$5,2)<6,COUNTIF(휴일!$A$2:$A$2,X$5)=0),2,IF(AND(ISNUMBER($K10),X$5>=$K10,X$5<=$L10,WEEKDAY(X$5,2)<6,COUNTIF(휴일!$A$2:$A$2,X$5)=0),1,"")) -> 2 | Y10: =IF(AND(ISNUMBER($M10),Y$5>=$M10,Y$5<=IF($N10="",$L$1,$N10),WEEKDAY(Y$5,2)<6,COUNTIF(휴일!$A$2:$A$2,Y$5)=0),2,IF(AND(ISNUMBER($K10),Y$5>=$K10,Y$5<=$L10,WEEKDAY(Y$5,2)<6,COUNTIF(휴일!$A$2:$A$2,Y$5)=0),1,"")) | Z10: =IF(AND(ISNUMBER($M10),Z$5>=$M10,Z$5<=IF($N10="",$L$1,$N10),WEEKDAY(Z$5,2)<6,COUNTIF(휴일!$A$2:$A$2,Z$5)=0),2,IF(AND(ISNUMBER($K10),Z$5>=$K10,Z$5<=$L10,WEEKDAY(Z$5,2)<6,COUNTIF(휴일!$A$2:$A$2,Z$5)=0),1,"")) | AA10: =IF(AND(ISNUMBER($M10),AA$5>=$M10,AA$5<=IF($N10="",$L$1,$N10),WEEKDAY(AA$5,2)<6,COUNTIF(휴일!$A$2:$A$2,AA$5)=0),2,IF(AND(ISNUMBER($K10),AA$5>=$K10,AA$5<=$L10,WEEKDAY(AA$5,2)<6,COUNTIF(휴일!$A$2:$A$2,AA$5)=0),1,"")) | AB10: =IF(AND(ISNUMBER($M10),AB$5>=$M10,AB$5<=IF($N10="",$L$1,$N10),WEEKDAY(AB$5,2)<6,COUNTIF(휴일!$A$2:$A$2,AB$5)=0),2,IF(AND(ISNUMBER($K10),AB$5>=$K10,AB$5<=$L10,WEEKDAY(AB$5,2)<6,COUNTIF(휴일!$A$2:$A$2,AB$5)=0),1,"")) | AC10: =IF(AND(ISNUMBER($M10),AC$5>=$M10,AC$5<=IF($N10="",$L$1,$N10),WEEKDAY(AC$5,2)<6,COUNTIF(휴일!$A$2:$A$2,AC$5)=0),2,IF(AND(ISNUMBER($K10),AC$5>=$K10,AC$5<=$L10,WEEKDAY(AC$5,2)<6,COUNTIF(휴일!$A$2:$A$2,AC$5)=0),1,"")) | AD10: =IF(AND(ISNUMBER($M10),AD$5>=$M10,AD$5<=IF($N10="",$L$1,$N10),WEEKDAY(AD$5,2)<6,COUNTIF(휴일!$A$2:$A$2,AD$5)=0),2,IF(AND(ISNUMBER($K10),AD$5>=$K10,AD$5<=$L10,WEEKDAY(AD$5,2)<6,COUNTIF(휴일!$A$2:$A$2,AD$5)=0),1,"")) | AE10: =IF(AND(ISNUMBER($M10),AE$5>=$M10,AE$5<=IF($N10="",$L$1,$N10),WEEKDAY(AE$5,2)<6,COUNTIF(휴일!$A$2:$A$2,AE$5)=0),2,IF(AND(ISNUMBER($K10),AE$5>=$K10,AE$5<=$L10,WEEKDAY(AE$5,2)<6,COUNTIF(휴일!$A$2:$A$2,AE$5)=0),1,"")) | AF10: 완료
B11: 2 | C11: 0.15289256 | D11: 환경·공간 구축 | F11: 2.01 Unity 버전·프로젝트·패키지 확인 | H11: 김찬중 | I11: 권오민 | J11: 환경 6000.4.0f1, URP 및 필요한 패키지 버전 고정 | K11: 46302 | L11: 46302 | M11: 46302 | N11: 46302 | O11: =IF(OR(K11="",L11=""),"",IF(L11<K11,"날짜 확인",NETWORKDAYS(K11,L11,휴일!$A$2:$A$2))) -> 1 | P11: =IF(OR(M11="",N11=""),"",IF(N11<M11,"날짜 확인",NETWORKDAYS(M11,N11,휴일!$A$2:$A$2))) -> 1 | Q11: =IF(O11="","",IF($L$1<K11,0,NETWORKDAYS(K11,MIN($L$1,L11),휴일!$A$2:$A$2))) -> 1 | R11: =IF(M11="","",IF($L$1<M11,0,NETWORKDAYS(M11,IF(N11="",$L$1,MIN($L$1,N11)),휴일!$A$2:$A$2))) -> 1 | S11: =IF(O11="","",IF(O11=0,0,Q11/O11)) -> 1 | T11: =IF(OR(AND(AG11<>"",OR(NOT(ISNUMBER(AG11)),AG11<=0)),AND(AH11<>"",OR(NOT(ISNUMBER(AH11)),AH11<0)),AND(ISNUMBER(AG11),ISNUMBER(AH11),AH11>AG11)),"수량 확인",IF(AF11="완료",1,IF(AF11="미착수",0,IF(AND(ISNUMBER(AG11),ISNUMBER(AH11)),AH11/AG11,"")))) -> 1 | U11: =IF(T11="","",T11) -> 1 | V11: =IF(OR(U11="",S11=""),"",U11-S11) -> 0 | W11: =IF(AND(ISNUMBER($M11),W$5>=$M11,W$5<=IF($N11="",$L$1,$N11),WEEKDAY(W$5,2)<6,COUNTIF(휴일!$A$2:$A$2,W$5)=0),2,IF(AND(ISNUMBER($K11),W$5>=$K11,W$5<=$L11,WEEKDAY(W$5,2)<6,COUNTIF(휴일!$A$2:$A$2,W$5)=0),1,"")) | X11: =IF(AND(ISNUMBER($M11),X$5>=$M11,X$5<=IF($N11="",$L$1,$N11),WEEKDAY(X$5,2)<6,COUNTIF(휴일!$A$2:$A$2,X$5)=0),2,IF(AND(ISNUMBER($K11),X$5>=$K11,X$5<=$L11,WEEKDAY(X$5,2)<6,COUNTIF(휴일!$A$2:$A$2,X$5)=0),1,"")) -> 2 | Y11: =IF(AND(ISNUMBER($M11),Y$5>=$M11,Y$5<=IF($N11="",$L$1,$N11),WEEKDAY(Y$5,2)<6,COUNTIF(휴일!$A$2:$A$2,Y$5)=0),2,IF(AND(ISNUMBER($K11),Y$5>=$K11,Y$5<=$L11,WEEKDAY(Y$5,2)<6,COUNTIF(휴일!$A$2:$A$2,Y$5)=0),1,"")) | Z11: =IF(AND(ISNUMBER($M11),Z$5>=$M11,Z$5<=IF($N11="",$L$1,$N11),WEEKDAY(Z$5,2)<6,COUNTIF(휴일!$A$2:$A$2,Z$5)=0),2,IF(AND(ISNUMBER($K11),Z$5>=$K11,Z$5<=$L11,WEEKDAY(Z$5,2)<6,COUNTIF(휴일!$A$2:$A$2,Z$5)=0),1,"")) | AA11: =IF(AND(ISNUMBER($M11),AA$5>=$M11,AA$5<=IF($N11="",$L$1,$N11),WEEKDAY(AA$5,2)<6,COUNTIF(휴일!$A$2:$A$2,AA$5)=0),2,IF(AND(ISNUMBER($K11),AA$5>=$K11,AA$5<=$L11,WEEKDAY(AA$5,2)<6,COUNTIF(휴일!$A$2:$A$2,AA$5)=0),1,"")) | AB11: =IF(AND(ISNUMBER($M11),AB$5>=$M11,AB$5<=IF($N11="",$L$1,$N11),WEEKDAY(AB$5,2)<6,COUNTIF(휴일!$A$2:$A$2,AB$5)=0),2,IF(AND(ISNUMBER($K11),AB$5>=$K11,AB$5<=$L11,WEEKDAY(AB$5,2)<6,COUNTIF(휴일!$A$2:$A$2,AB$5)=0),1,"")) | AC11: =IF(AND(ISNUMBER($M11),AC$5>=$M11,AC$5<=IF($N11="",$L$1,$N11),WEEKDAY(AC$5,2)<6,COUNTIF(휴일!$A$2:$A$2,AC$5)=0),2,IF(AND(ISNUMBER($K11),AC$5>=$K11,AC$5<=$L11,WEEKDAY(AC$5,2)<6,COUNTIF(휴일!$A$2:$A$2,AC$5)=0),1,"")) | AD11: =IF(AND(ISNUMBER($M11),AD$5>=$M11,AD$5<=IF($N11="",$L$1,$N11),WEEKDAY(AD$5,2)<6,COUNTIF(휴일!$A$2:$A$2,AD$5)=0),2,IF(AND(ISNUMBER($K11),AD$5>=$K11,AD$5<=$L11,WEEKDAY(AD$5,2)<6,COUNTIF(휴일!$A$2:$A$2,AD$5)=0),1,"")) | AE11: =IF(AND(ISNUMBER($M11),AE$5>=$M11,AE$5<=IF($N11="",$L$1,$N11),WEEKDAY(AE$5,2)<6,COUNTIF(휴일!$A$2:$A$2,AE$5)=0),2,IF(AND(ISNUMBER($K11),AE$5>=$K11,AE$5<=$L11,WEEKDAY(AE$5,2)<6,COUNTIF(휴일!$A$2:$A$2,AE$5)=0),1,"")) | AF11: 완료
F12: 2.02 Git 제외 경로·메타 관리 설정 | H12: 김찬중 | I12: 권오민 | J12: 환경 Library·빌드·ThirdParty 제외, 메타와 원본 쌍 확인 | K12: 46302 | L12: 46302 | M12: 46302 | N12: 46302 | O12: =IF(OR(K12="",L12=""),"",IF(L12<K12,"날짜 확인",NETWORKDAYS(K12,L12,휴일!$A$2:$A$2))) -> 1 | P12: =IF(OR(M12="",N12=""),"",IF(N12<M12,"날짜 확인",NETWORKDAYS(M12,N12,휴일!$A$2:$A$2))) -> 1 | Q12: =IF(O12="","",IF($L$1<K12,0,NETWORKDAYS(K12,MIN($L$1,L12),휴일!$A$2:$A$2))) -> 1 | R12: =IF(M12="","",IF($L$1<M12,0,NETWORKDAYS(M12,IF(N12="",$L$1,MIN($L$1,N12)),휴일!$A$2:$A$2))) -> 1 | S12: =IF(O12="","",IF(O12=0,0,Q12/O12)) -> 1 | T12: =IF(OR(AND(AG12<>"",OR(NOT(ISNUMBER(AG12)),AG12<=0)),AND(AH12<>"",OR(NOT(ISNUMBER(AH12)),AH12<0)),AND(ISNUMBER(AG12),ISNUMBER(AH12),AH12>AG12)),"수량 확인",IF(AF12="완료",1,IF(AF12="미착수",0,IF(AND(ISNUMBER(AG12),ISNUMBER(AH12)),AH12/AG12,"")))) -> 1 | U12: =IF(T12="","",T12) -> 1 | V12: =IF(OR(U12="",S12=""),"",U12-S12) -> 0 | W12: =IF(AND(ISNUMBER($M12),W$5>=$M12,W$5<=IF($N12="",$L$1,$N12),WEEKDAY(W$5,2)<6,COUNTIF(휴일!$A$2:$A$2,W$5)=0),2,IF(AND(ISNUMBER($K12),W$5>=$K12,W$5<=$L12,WEEKDAY(W$5,2)<6,COUNTIF(휴일!$A$2:$A$2,W$5)=0),1,"")) | X12: =IF(AND(ISNUMBER($M12),X$5>=$M12,X$5<=IF($N12="",$L$1,$N12),WEEKDAY(X$5,2)<6,COUNTIF(휴일!$A$2:$A$2,X$5)=0),2,IF(AND(ISNUMBER($K12),X$5>=$K12,X$5<=$L12,WEEKDAY(X$5,2)<6,COUNTIF(휴일!$A$2:$A$2,X$5)=0),1,"")) -> 2 | Y12: =IF(AND(ISNUMBER($M12),Y$5>=$M12,Y$5<=IF($N12="",$L$1,$N12),WEEKDAY(Y$5,2)<6,COUNTIF(휴일!$A$2:$A$2,Y$5)=0),2,IF(AND(ISNUMBER($K12),Y$5>=$K12,Y$5<=$L12,WEEKDAY(Y$5,2)<6,COUNTIF(휴일!$A$2:$A$2,Y$5)=0),1,"")) | Z12: =IF(AND(ISNUMBER($M12),Z$5>=$M12,Z$5<=IF($N12="",$L$1,$N12),WEEKDAY(Z$5,2)<6,COUNTIF(휴일!$A$2:$A$2,Z$5)=0),2,IF(AND(ISNUMBER($K12),Z$5>=$K12,Z$5<=$L12,WEEKDAY(Z$5,2)<6,COUNTIF(휴일!$A$2:$A$2,Z$5)=0),1,"")) | AA12: =IF(AND(ISNUMBER($M12),AA$5>=$M12,AA$5<=IF($N12="",$L$1,$N12),WEEKDAY(AA$5,2)<6,COUNTIF(휴일!$A$2:$A$2,AA$5)=0),2,IF(AND(ISNUMBER($K12),AA$5>=$K12,AA$5<=$L12,WEEKDAY(AA$5,2)<6,COUNTIF(휴일!$A$2:$A$2,AA$5)=0),1,"")) | AB12: =IF(AND(ISNUMBER($M12),AB$5>=$M12,AB$5<=IF($N12="",$L$1,$N12),WEEKDAY(AB$5,2)<6,COUNTIF(휴일!$A$2:$A$2,AB$5)=0),2,IF(AND(ISNUMBER($K12),AB$5>=$K12,AB$5<=$L12,WEEKDAY(AB$5,2)<6,COUNTIF(휴일!$A$2:$A$2,AB$5)=0),1,"")) | AC12: =IF(AND(ISNUMBER($M12),AC$5>=$M12,AC$5<=IF($N12="",$L$1,$N12),WEEKDAY(AC$5,2)<6,COUNTIF(휴일!$A$2:$A$2,AC$5)=0),2,IF(AND(ISNUMBER($K12),AC$5>=$K12,AC$5<=$L12,WEEKDAY(AC$5,2)<6,COUNTIF(휴일!$A$2:$A$2,AC$5)=0),1,"")) | AD12: =IF(AND(ISNUMBER($M12),AD$5>=$M12,AD$5<=IF($N12="",$L$1,$N12),WEEKDAY(AD$5,2)<6,COUNTIF(휴일!$A$2:$A$2,AD$5)=0),2,IF(AND(ISNUMBER($K12),AD$5>=$K12,AD$5<=$L12,WEEKDAY(AD$5,2)<6,COUNTIF(휴일!$A$2:$A$2,AD$5)=0),1,"")) | AE12: =IF(AND(ISNUMBER($M12),AE$5>=$M12,AE$5<=IF($N12="",$L$1,$N12),WEEKDAY(AE$5,2)<6,COUNTIF(휴일!$A$2:$A$2,AE$5)=0),2,IF(AND(ISNUMBER($K12),AE$5>=$K12,AE$5<=$L12,WEEKDAY(AE$5,2)<6,COUNTIF(휴일!$A$2:$A$2,AE$5)=0),1,"")) | AF12: 완료
F13: 2.03 아파트 에셋 가져오기·Main 구성 | H13: 권오민 | I13: 김찬중 | J13: NFR-03 누락 재질 없이 Main 실행, 원본 별도 보관 | K13: 46302 | L13: 46302 | M13: 46302 | N13: 46303 | O13: =IF(OR(K13="",L13=""),"",IF(L13<K13,"날짜 확인",NETWORKDAYS(K13,L13,휴일!$A$2:$A$2))) -> 1 | P13: =IF(OR(M13="",N13=""),"",IF(N13<M13,"날짜 확인",NETWORKDAYS(M13,N13,휴일!$A$2:$A$2))) -> 2 | Q13: =IF(O13="","",IF($L$1<K13,0,NETWORKDAYS(K13,MIN($L$1,L13),휴일!$A$2:$A$2))) -> 1 | R13: =IF(M13="","",IF($L$1<M13,0,NETWORKDAYS(M13,IF(N13="",$L$1,MIN($L$1,N13)),휴일!$A$2:$A$2))) -> 2 | S13: =IF(O13="","",IF(O13=0,0,Q13/O13)) -> 1 | T13: =IF(OR(AND(AG13<>"",OR(NOT(ISNUMBER(AG13)),AG13<=0)),AND(AH13<>"",OR(NOT(ISNUMBER(AH13)),AH13<0)),AND(ISNUMBER(AG13),ISNUMBER(AH13),AH13>AG13)),"수량 확인",IF(AF13="완료",1,IF(AF13="미착수",0,IF(AND(ISNUMBER(AG13),ISNUMBER(AH13)),AH13/AG13,"")))) -> 1 | U13: =IF(T13="","",T13) -> 1 | V13: =IF(OR(U13="",S13=""),"",U13-S13) -> 0 | W13: =IF(AND(ISNUMBER($M13),W$5>=$M13,W$5<=IF($N13="",$L$1,$N13),WEEKDAY(W$5,2)<6,COUNTIF(휴일!$A$2:$A$2,W$5)=0),2,IF(AND(ISNUMBER($K13),W$5>=$K13,W$5<=$L13,WEEKDAY(W$5,2)<6,COUNTIF(휴일!$A$2:$A$2,W$5)=0),1,"")) | X13: =IF(AND(ISNUMBER($M13),X$5>=$M13,X$5<=IF($N13="",$L$1,$N13),WEEKDAY(X$5,2)<6,COUNTIF(휴일!$A$2:$A$2,X$5)=0),2,IF(AND(ISNUMBER($K13),X$5>=$K13,X$5<=$L13,WEEKDAY(X$5,2)<6,COUNTIF(휴일!$A$2:$A$2,X$5)=0),1,"")) -> 2 | Y13: =IF(AND(ISNUMBER($M13),Y$5>=$M13,Y$5<=IF($N13="",$L$1,$N13),WEEKDAY(Y$5,2)<6,COUNTIF(휴일!$A$2:$A$2,Y$5)=0),2,IF(AND(ISNUMBER($K13),Y$5>=$K13,Y$5<=$L13,WEEKDAY(Y$5,2)<6,COUNTIF(휴일!$A$2:$A$2,Y$5)=0),1,"")) -> 2 | Z13: =IF(AND(ISNUMBER($M13),Z$5>=$M13,Z$5<=IF($N13="",$L$1,$N13),WEEKDAY(Z$5,2)<6,COUNTIF(휴일!$A$2:$A$2,Z$5)=0),2,IF(AND(ISNUMBER($K13),Z$5>=$K13,Z$5<=$L13,WEEKDAY(Z$5,2)<6,COUNTIF(휴일!$A$2:$A$2,Z$5)=0),1,"")) | AA13: =IF(AND(ISNUMBER($M13),AA$5>=$M13,AA$5<=IF($N13="",$L$1,$N13),WEEKDAY(AA$5,2)<6,COUNTIF(휴일!$A$2:$A$2,AA$5)=0),2,IF(AND(ISNUMBER($K13),AA$5>=$K13,AA$5<=$L13,WEEKDAY(AA$5,2)<6,COUNTIF(휴일!$A$2:$A$2,AA$5)=0),1,"")) | AB13: =IF(AND(ISNUMBER($M13),AB$5>=$M13,AB$5<=IF($N13="",$L$1,$N13),WEEKDAY(AB$5,2)<6,COUNTIF(휴일!$A$2:$A$2,AB$5)=0),2,IF(AND(ISNUMBER($K13),AB$5>=$K13,AB$5<=$L13,WEEKDAY(AB$5,2)<6,COUNTIF(휴일!$A$2:$A$2,AB$5)=0),1,"")) | AC13: =IF(AND(ISNUMBER($M13),AC$5>=$M13,AC$5<=IF($N13="",$L$1,$N13),WEEKDAY(AC$5,2)<6,COUNTIF(휴일!$A$2:$A$2,AC$5)=0),2,IF(AND(ISNUMBER($K13),AC$5>=$K13,AC$5<=$L13,WEEKDAY(AC$5,2)<6,COUNTIF(휴일!$A$2:$A$2,AC$5)=0),1,"")) | AD13: =IF(AND(ISNUMBER($M13),AD$5>=$M13,AD$5<=IF($N13="",$L$1,$N13),WEEKDAY(AD$5,2)<6,COUNTIF(휴일!$A$2:$A$2,AD$5)=0),2,IF(AND(ISNUMBER($K13),AD$5>=$K13,AD$5<=$L13,WEEKDAY(AD$5,2)<6,COUNTIF(휴일!$A$2:$A$2,AD$5)=0),1,"")) | AE13: =IF(AND(ISNUMBER($M13),AE$5>=$M13,AE$5<=IF($N13="",$L$1,$N13),WEEKDAY(AE$5,2)<6,COUNTIF(휴일!$A$2:$A$2,AE$5)=0),2,IF(AND(ISNUMBER($K13),AE$5>=$K13,AE$5<=$L13,WEEKDAY(AE$5,2)<6,COUNTIF(휴일!$A$2:$A$2,AE$5)=0),1,"")) | AF13: 완료
F14: 2.04 스케일·문 높이·충돌체 정리 | H14: 권오민 | I14: 김찬중 | J14: FR-01,NFR-03 1unit=1m, scale1, 문 높이 에셋 기본(약 2.5m), 벽 관통 방지 | K14: 46302 | L14: 46302 | M14: 46303 | N14: 46307 | O14: =IF(OR(K14="",L14=""),"",IF(L14<K14,"날짜 확인",NETWORKDAYS(K14,L14,휴일!$A$2:$A$2))) -> 1 | P14: =IF(OR(M14="",N14=""),"",IF(N14<M14,"날짜 확인",NETWORKDAYS(M14,N14,휴일!$A$2:$A$2))) -> 2 | Q14: =IF(O14="","",IF($L$1<K14,0,NETWORKDAYS(K14,MIN($L$1,L14),휴일!$A$2:$A$2))) -> 1 | R14: =IF(M14="","",IF($L$1<M14,0,NETWORKDAYS(M14,IF(N14="",$L$1,MIN($L$1,N14)),휴일!$A$2:$A$2))) -> 2 | S14: =IF(O14="","",IF(O14=0,0,Q14/O14)) -> 1 | T14: =IF(OR(AND(AG14<>"",OR(NOT(ISNUMBER(AG14)),AG14<=0)),AND(AH14<>"",OR(NOT(ISNUMBER(AH14)),AH14<0)),AND(ISNUMBER(AG14),ISNUMBER(AH14),AH14>AG14)),"수량 확인",IF(AF14="완료",1,IF(AF14="미착수",0,IF(AND(ISNUMBER(AG14),ISNUMBER(AH14)),AH14/AG14,"")))) -> 1 | U14: =IF(T14="","",T14) -> 1 | V14: =IF(OR(U14="",S14=""),"",U14-S14) -> 0 | W14: =IF(AND(ISNUMBER($M14),W$5>=$M14,W$5<=IF($N14="",$L$1,$N14),WEEKDAY(W$5,2)<6,COUNTIF(휴일!$A$2:$A$2,W$5)=0),2,IF(AND(ISNUMBER($K14),W$5>=$K14,W$5<=$L14,WEEKDAY(W$5,2)<6,COUNTIF(휴일!$A$2:$A$2,W$5)=0),1,"")) | X14: =IF(AND(ISNUMBER($M14),X$5>=$M14,X$5<=IF($N14="",$L$1,$N14),WEEKDAY(X$5,2)<6,COUNTIF(휴일!$A$2:$A$2,X$5)=0),2,IF(AND(ISNUMBER($K14),X$5>=$K14,X$5<=$L14,WEEKDAY(X$5,2)<6,COUNTIF(휴일!$A$2:$A$2,X$5)=0),1,"")) -> 1 | Y14: =IF(AND(ISNUMBER($M14),Y$5>=$M14,Y$5<=IF($N14="",$L$1,$N14),WEEKDAY(Y$5,2)<6,COUNTIF(휴일!$A$2:$A$2,Y$5)=0),2,IF(AND(ISNUMBER($K14),Y$5>=$K14,Y$5<=$L14,WEEKDAY(Y$5,2)<6,COUNTIF(휴일!$A$2:$A$2,Y$5)=0),1,"")) -> 2 | Z14: =IF(AND(ISNUMBER($M14),Z$5>=$M14,Z$5<=IF($N14="",$L$1,$N14),WEEKDAY(Z$5,2)<6,COUNTIF(휴일!$A$2:$A$2,Z$5)=0),2,IF(AND(ISNUMBER($K14),Z$5>=$K14,Z$5<=$L14,WEEKDAY(Z$5,2)<6,COUNTIF(휴일!$A$2:$A$2,Z$5)=0),1,"")) | AA14: =IF(AND(ISNUMBER($M14),AA$5>=$M14,AA$5<=IF($N14="",$L$1,$N14),WEEKDAY(AA$5,2)<6,COUNTIF(휴일!$A$2:$A$2,AA$5)=0),2,IF(AND(ISNUMBER($K14),AA$5>=$K14,AA$5<=$L14,WEEKDAY(AA$5,2)<6,COUNTIF(휴일!$A$2:$A$2,AA$5)=0),1,"")) | AB14: =IF(AND(ISNUMBER($M14),AB$5>=$M14,AB$5<=IF($N14="",$L$1,$N14),WEEKDAY(AB$5,2)<6,COUNTIF(휴일!$A$2:$A$2,AB$5)=0),2,IF(AND(ISNUMBER($K14),AB$5>=$K14,AB$5<=$L14,WEEKDAY(AB$5,2)<6,COUNTIF(휴일!$A$2:$A$2,AB$5)=0),1,"")) | AC14: =IF(AND(ISNUMBER($M14),AC$5>=$M14,AC$5<=IF($N14="",$L$1,$N14),WEEKDAY(AC$5,2)<6,COUNTIF(휴일!$A$2:$A$2,AC$5)=0),2,IF(AND(ISNUMBER($K14),AC$5>=$K14,AC$5<=$L14,WEEKDAY(AC$5,2)<6,COUNTIF(휴일!$A$2:$A$2,AC$5)=0),1,"")) -> 2 | AD14: =IF(AND(ISNUMBER($M14),AD$5>=$M14,AD$5<=IF($N14="",$L$1,$N14),WEEKDAY(AD$5,2)<6,COUNTIF(휴일!$A$2:$A$2,AD$5)=0),2,IF(AND(ISNUMBER($K14),AD$5>=$K14,AD$5<=$L14,WEEKDAY(AD$5,2)<6,COUNTIF(휴일!$A$2:$A$2,AD$5)=0),1,"")) | AE14: =IF(AND(ISNUMBER($M14),AE$5>=$M14,AE$5<=IF($N14="",$L$1,$N14),WEEKDAY(AE$5,2)<6,COUNTIF(휴일!$A$2:$A$2,AE$5)=0),2,IF(AND(ISNUMBER($K14),AE$5>=$K14,AE$5<=$L14,WEEKDAY(AE$5,2)<6,COUNTIF(휴일!$A$2:$A$2,AE$5)=0),1,"")) | AF14: 완료
F15: 2.05 4개 구역·입구·거실주방 경계 배치 | H15: 권오민 | I15: 김찬중 | J15: FR-02/04/05 현관·거실·주방·침실 구역과 통과 방향 지정 | K15: 46302 | L15: 46302 | M15: 46303 | N15: 46303 | O15: =IF(OR(K15="",L15=""),"",IF(L15<K15,"날짜 확인",NETWORKDAYS(K15,L15,휴일!$A$2:$A$2))) -> 1 | P15: =IF(OR(M15="",N15=""),"",IF(N15<M15,"날짜 확인",NETWORKDAYS(M15,N15,휴일!$A$2:$A$2))) -> 1 | Q15: =IF(O15="","",IF($L$1<K15,0,NETWORKDAYS(K15,MIN($L$1,L15),휴일!$A$2:$A$2))) -> 1 | R15: =IF(M15="","",IF($L$1<M15,0,NETWORKDAYS(M15,IF(N15="",$L$1,MIN($L$1,N15)),휴일!$A$2:$A$2))) -> 1 | S15: =IF(O15="","",IF(O15=0,0,Q15/O15)) -> 1 | T15: =IF(OR(AND(AG15<>"",OR(NOT(ISNUMBER(AG15)),AG15<=0)),AND(AH15<>"",OR(NOT(ISNUMBER(AH15)),AH15<0)),AND(ISNUMBER(AG15),ISNUMBER(AH15),AH15>AG15)),"수량 확인",IF(AF15="완료",1,IF(AF15="미착수",0,IF(AND(ISNUMBER(AG15),ISNUMBER(AH15)),AH15/AG15,"")))) -> 1 | U15: =IF(T15="","",T15) -> 1 | V15: =IF(OR(U15="",S15=""),"",U15-S15) -> 0 | W15: =IF(AND(ISNUMBER($M15),W$5>=$M15,W$5<=IF($N15="",$L$1,$N15),WEEKDAY(W$5,2)<6,COUNTIF(휴일!$A$2:$A$2,W$5)=0),2,IF(AND(ISNUMBER($K15),W$5>=$K15,W$5<=$L15,WEEKDAY(W$5,2)<6,COUNTIF(휴일!$A$2:$A$2,W$5)=0),1,"")) | X15: =IF(AND(ISNUMBER($M15),X$5>=$M15,X$5<=IF($N15="",$L$1,$N15),WEEKDAY(X$5,2)<6,COUNTIF(휴일!$A$2:$A$2,X$5)=0),2,IF(AND(ISNUMBER($K15),X$5>=$K15,X$5<=$L15,WEEKDAY(X$5,2)<6,COUNTIF(휴일!$A$2:$A$2,X$5)=0),1,"")) -> 1 | Y15: =IF(AND(ISNUMBER($M15),Y$5>=$M15,Y$5<=IF($N15="",$L$1,$N15),WEEKDAY(Y$5,2)<6,COUNTIF(휴일!$A$2:$A$2,Y$5)=0),2,IF(AND(ISNUMBER($K15),Y$5>=$K15,Y$5<=$L15,WEEKDAY(Y$5,2)<6,COUNTIF(휴일!$A$2:$A$2,Y$5)=0),1,"")) -> 2 | Z15: =IF(AND(ISNUMBER($M15),Z$5>=$M15,Z$5<=IF($N15="",$L$1,$N15),WEEKDAY(Z$5,2)<6,COUNTIF(휴일!$A$2:$A$2,Z$5)=0),2,IF(AND(ISNUMBER($K15),Z$5>=$K15,Z$5<=$L15,WEEKDAY(Z$5,2)<6,COUNTIF(휴일!$A$2:$A$2,Z$5)=0),1,"")) | AA15: =IF(AND(ISNUMBER($M15),AA$5>=$M15,AA$5<=IF($N15="",$L$1,$N15),WEEKDAY(AA$5,2)<6,COUNTIF(휴일!$A$2:$A$2,AA$5)=0),2,IF(AND(ISNUMBER($K15),AA$5>=$K15,AA$5<=$L15,WEEKDAY(AA$5,2)<6,COUNTIF(휴일!$A$2:$A$2,AA$5)=0),1,"")) | AB15: =IF(AND(ISNUMBER($M15),AB$5>=$M15,AB$5<=IF($N15="",$L$1,$N15),WEEKDAY(AB$5,2)<6,COUNTIF(휴일!$A$2:$A$2,AB$5)=0),2,IF(AND(ISNUMBER($K15),AB$5>=$K15,AB$5<=$L15,WEEKDAY(AB$5,2)<6,COUNTIF(휴일!$A$2:$A$2,AB$5)=0),1,"")) | AC15: =IF(AND(ISNUMBER($M15),AC$5>=$M15,AC$5<=IF($N15="",$L$1,$N15),WEEKDAY(AC$5,2)<6,COUNTIF(휴일!$A$2:$A$2,AC$5)=0),2,IF(AND(ISNUMBER($K15),AC$5>=$K15,AC$5<=$L15,WEEKDAY(AC$5,2)<6,COUNTIF(휴일!$A$2:$A$2,AC$5)=0),1,"")) | AD15: =IF(AND(ISNUMBER($M15),AD$5>=$M15,AD$5<=IF($N15="",$L$1,$N15),WEEKDAY(AD$5,2)<6,COUNTIF(휴일!$A$2:$A$2,AD$5)=0),2,IF(AND(ISNUMBER($K15),AD$5>=$K15,AD$5<=$L15,WEEKDAY(AD$5,2)<6,COUNTIF(휴일!$A$2:$A$2,AD$5)=0),1,"")) | AE15: =IF(AND(ISNUMBER($M15),AE$5>=$M15,AE$5<=IF($N15="",$L$1,$N15),WEEKDAY(AE$5,2)<6,COUNTIF(휴일!$A$2:$A$2,AE$5)=0),2,IF(AND(ISNUMBER($K15),AE$5>=$K15,AE$5<=$L15,WEEKDAY(AE$5,2)<6,COUNTIF(휴일!$A$2:$A$2,AE$5)=0),1,"")) | AF15: 완료
F16: 2.06 벽·바닥 등 옵션 대상 7종 분리 | H16: 권오민 | I16: 김찬중 | J16: FR-29 모든 교체 대상 등록, 원본 공유 재질 보존 | K16: 46302 | L16: 46302 | M16: 46303 | N16: 46307 | O16: =IF(OR(K16="",L16=""),"",IF(L16<K16,"날짜 확인",NETWORKDAYS(K16,L16,휴일!$A$2:$A$2))) -> 1 | P16: =IF(OR(M16="",N16=""),"",IF(N16<M16,"날짜 확인",NETWORKDAYS(M16,N16,휴일!$A$2:$A$2))) -> 2 | Q16: =IF(O16="","",IF($L$1<K16,0,NETWORKDAYS(K16,MIN($L$1,L16),휴일!$A$2:$A$2))) -> 1 | R16: =IF(M16="","",IF($L$1<M16,0,NETWORKDAYS(M16,IF(N16="",$L$1,MIN($L$1,N16)),휴일!$A$2:$A$2))) -> 2 | S16: =IF(O16="","",IF(O16=0,0,Q16/O16)) -> 1 | T16: =IF(OR(AND(AG16<>"",OR(NOT(ISNUMBER(AG16)),AG16<=0)),AND(AH16<>"",OR(NOT(ISNUMBER(AH16)),AH16<0)),AND(ISNUMBER(AG16),ISNUMBER(AH16),AH16>AG16)),"수량 확인",IF(AF16="완료",1,IF(AF16="미착수",0,IF(AND(ISNUMBER(AG16),ISNUMBER(AH16)),AH16/AG16,"")))) -> 1 | U16: =IF(T16="","",T16) -> 1 | V16: =IF(OR(U16="",S16=""),"",U16-S16) -> 0 | W16: =IF(AND(ISNUMBER($M16),W$5>=$M16,W$5<=IF($N16="",$L$1,$N16),WEEKDAY(W$5,2)<6,COUNTIF(휴일!$A$2:$A$2,W$5)=0),2,IF(AND(ISNUMBER($K16),W$5>=$K16,W$5<=$L16,WEEKDAY(W$5,2)<6,COUNTIF(휴일!$A$2:$A$2,W$5)=0),1,"")) | X16: =IF(AND(ISNUMBER($M16),X$5>=$M16,X$5<=IF($N16="",$L$1,$N16),WEEKDAY(X$5,2)<6,COUNTIF(휴일!$A$2:$A$2,X$5)=0),2,IF(AND(ISNUMBER($K16),X$5>=$K16,X$5<=$L16,WEEKDAY(X$5,2)<6,COUNTIF(휴일!$A$2:$A$2,X$5)=0),1,"")) -> 1 | Y16: =IF(AND(ISNUMBER($M16),Y$5>=$M16,Y$5<=IF($N16="",$L$1,$N16),WEEKDAY(Y$5,2)<6,COUNTIF(휴일!$A$2:$A$2,Y$5)=0),2,IF(AND(ISNUMBER($K16),Y$5>=$K16,Y$5<=$L16,WEEKDAY(Y$5,2)<6,COUNTIF(휴일!$A$2:$A$2,Y$5)=0),1,"")) -> 2 | Z16: =IF(AND(ISNUMBER($M16),Z$5>=$M16,Z$5<=IF($N16="",$L$1,$N16),WEEKDAY(Z$5,2)<6,COUNTIF(휴일!$A$2:$A$2,Z$5)=0),2,IF(AND(ISNUMBER($K16),Z$5>=$K16,Z$5<=$L16,WEEKDAY(Z$5,2)<6,COUNTIF(휴일!$A$2:$A$2,Z$5)=0),1,"")) | AA16: =IF(AND(ISNUMBER($M16),AA$5>=$M16,AA$5<=IF($N16="",$L$1,$N16),WEEKDAY(AA$5,2)<6,COUNTIF(휴일!$A$2:$A$2,AA$5)=0),2,IF(AND(ISNUMBER($K16),AA$5>=$K16,AA$5<=$L16,WEEKDAY(AA$5,2)<6,COUNTIF(휴일!$A$2:$A$2,AA$5)=0),1,"")) | AB16: =IF(AND(ISNUMBER($M16),AB$5>=$M16,AB$5<=IF($N16="",$L$1,$N16),WEEKDAY(AB$5,2)<6,COUNTIF(휴일!$A$2:$A$2,AB$5)=0),2,IF(AND(ISNUMBER($K16),AB$5>=$K16,AB$5<=$L16,WEEKDAY(AB$5,2)<6,COUNTIF(휴일!$A$2:$A$2,AB$5)=0),1,"")) | AC16: =IF(AND(ISNUMBER($M16),AC$5>=$M16,AC$5<=IF($N16="",$L$1,$N16),WEEKDAY(AC$5,2)<6,COUNTIF(휴일!$A$2:$A$2,AC$5)=0),2,IF(AND(ISNUMBER($K16),AC$5>=$K16,AC$5<=$L16,WEEKDAY(AC$5,2)<6,COUNTIF(휴일!$A$2:$A$2,AC$5)=0),1,"")) -> 2 | AD16: =IF(AND(ISNUMBER($M16),AD$5>=$M16,AD$5<=IF($N16="",$L$1,$N16),WEEKDAY(AD$5,2)<6,COUNTIF(휴일!$A$2:$A$2,AD$5)=0),2,IF(AND(ISNUMBER($K16),AD$5>=$K16,AD$5<=$L16,WEEKDAY(AD$5,2)<6,COUNTIF(휴일!$A$2:$A$2,AD$5)=0),1,"")) | AE16: =IF(AND(ISNUMBER($M16),AE$5>=$M16,AE$5<=IF($N16="",$L$1,$N16),WEEKDAY(AE$5,2)<6,COUNTIF(휴일!$A$2:$A$2,AE$5)=0),2,IF(AND(ISNUMBER($K16),AE$5>=$K16,AE$5<=$L16,WEEKDAY(AE$5,2)<6,COUNTIF(휴일!$A$2:$A$2,AE$5)=0),1,"")) | AF16: 완료
F17: 2.07 6축 관절·그리퍼 프리팹 구성 | H17: 김찬중 | I17: 권오민 | J17: FR-15 축·회전 제한·홈 자세 기록, 테스트 씬 분리 | K17: 46302 | L17: 46302 | M17: 46303 | N17: 46307 | O17: =IF(OR(K17="",L17=""),"",IF(L17<K17,"날짜 확인",NETWORKDAYS(K17,L17,휴일!$A$2:$A$2))) -> 1 | P17: =IF(OR(M17="",N17=""),"",IF(N17<M17,"날짜 확인",NETWORKDAYS(M17,N17,휴일!$A$2:$A$2))) -> 2 | Q17: =IF(O17="","",IF($L$1<K17,0,NETWORKDAYS(K17,MIN($L$1,L17),휴일!$A$2:$A$2))) -> 1 | R17: =IF(M17="","",IF($L$1<M17,0,NETWORKDAYS(M17,IF(N17="",$L$1,MIN($L$1,N17)),휴일!$A$2:$A$2))) -> 2 | S17: =IF(O17="","",IF(O17=0,0,Q17/O17)) -> 1 | T17: =IF(OR(AND(AG17<>"",OR(NOT(ISNUMBER(AG17)),AG17<=0)),AND(AH17<>"",OR(NOT(ISNUMBER(AH17)),AH17<0)),AND(ISNUMBER(AG17),ISNUMBER(AH17),AH17>AG17)),"수량 확인",IF(AF17="완료",1,IF(AF17="미착수",0,IF(AND(ISNUMBER(AG17),ISNUMBER(AH17)),AH17/AG17,"")))) -> 1 | U17: =IF(T17="","",T17) -> 1 | V17: =IF(OR(U17="",S17=""),"",U17-S17) -> 0 | W17: =IF(AND(ISNUMBER($M17),W$5>=$M17,W$5<=IF($N17="",$L$1,$N17),WEEKDAY(W$5,2)<6,COUNTIF(휴일!$A$2:$A$2,W$5)=0),2,IF(AND(ISNUMBER($K17),W$5>=$K17,W$5<=$L17,WEEKDAY(W$5,2)<6,COUNTIF(휴일!$A$2:$A$2,W$5)=0),1,"")) | X17: =IF(AND(ISNUMBER($M17),X$5>=$M17,X$5<=IF($N17="",$L$1,$N17),WEEKDAY(X$5,2)<6,COUNTIF(휴일!$A$2:$A$2,X$5)=0),2,IF(AND(ISNUMBER($K17),X$5>=$K17,X$5<=$L17,WEEKDAY(X$5,2)<6,COUNTIF(휴일!$A$2:$A$2,X$5)=0),1,"")) -> 1 | Y17: =IF(AND(ISNUMBER($M17),Y$5>=$M17,Y$5<=IF($N17="",$L$1,$N17),WEEKDAY(Y$5,2)<6,COUNTIF(휴일!$A$2:$A$2,Y$5)=0),2,IF(AND(ISNUMBER($K17),Y$5>=$K17,Y$5<=$L17,WEEKDAY(Y$5,2)<6,COUNTIF(휴일!$A$2:$A$2,Y$5)=0),1,"")) -> 2 | Z17: =IF(AND(ISNUMBER($M17),Z$5>=$M17,Z$5<=IF($N17="",$L$1,$N17),WEEKDAY(Z$5,2)<6,COUNTIF(휴일!$A$2:$A$2,Z$5)=0),2,IF(AND(ISNUMBER($K17),Z$5>=$K17,Z$5<=$L17,WEEKDAY(Z$5,2)<6,COUNTIF(휴일!$A$2:$A$2,Z$5)=0),1,"")) | AA17: =IF(AND(ISNUMBER($M17),AA$5>=$M17,AA$5<=IF($N17="",$L$1,$N17),WEEKDAY(AA$5,2)<6,COUNTIF(휴일!$A$2:$A$2,AA$5)=0),2,IF(AND(ISNUMBER($K17),AA$5>=$K17,AA$5<=$L17,WEEKDAY(AA$5,2)<6,COUNTIF(휴일!$A$2:$A$2,AA$5)=0),1,"")) | AB17: =IF(AND(ISNUMBER($M17),AB$5>=$M17,AB$5<=IF($N17="",$L$1,$N17),WEEKDAY(AB$5,2)<6,COUNTIF(휴일!$A$2:$A$2,AB$5)=0),2,IF(AND(ISNUMBER($K17),AB$5>=$K17,AB$5<=$L17,WEEKDAY(AB$5,2)<6,COUNTIF(휴일!$A$2:$A$2,AB$5)=0),1,"")) | AC17: =IF(AND(ISNUMBER($M17),AC$5>=$M17,AC$5<=IF($N17="",$L$1,$N17),WEEKDAY(AC$5,2)<6,COUNTIF(휴일!$A$2:$A$2,AC$5)=0),2,IF(AND(ISNUMBER($K17),AC$5>=$K17,AC$5<=$L17,WEEKDAY(AC$5,2)<6,COUNTIF(휴일!$A$2:$A$2,AC$5)=0),1,"")) -> 2 | AD17: =IF(AND(ISNUMBER($M17),AD$5>=$M17,AD$5<=IF($N17="",$L$1,$N17),WEEKDAY(AD$5,2)<6,COUNTIF(휴일!$A$2:$A$2,AD$5)=0),2,IF(AND(ISNUMBER($K17),AD$5>=$K17,AD$5<=$L17,WEEKDAY(AD$5,2)<6,COUNTIF(휴일!$A$2:$A$2,AD$5)=0),1,"")) | AE17: =IF(AND(ISNUMBER($M17),AE$5>=$M17,AE$5<=IF($N17="",$L$1,$N17),WEEKDAY(AE$5,2)<6,COUNTIF(휴일!$A$2:$A$2,AE$5)=0),2,IF(AND(ISNUMBER($K17),AE$5>=$K17,AE$5<=$L17,WEEKDAY(AE$5,2)<6,COUNTIF(휴일!$A$2:$A$2,AE$5)=0),1,"")) | AF17: 완료
F18: 2.08 커피머신·컵·목표 지점 배치 | H18: 김찬중 | I18: 권오민 | J18: FR-13/15 컵 보관대(컵3)·찻잔 받침대·커피 머신·싱크대, 밑동에서 0.60m 이내 | K18: 46302 | L18: 46302 | M18: 46303 | N18: 46307 | O18: =IF(OR(K18="",L18=""),"",IF(L18<K18,"날짜 확인",NETWORKDAYS(K18,L18,휴일!$A$2:$A$2))) -> 1 | P18: =IF(OR(M18="",N18=""),"",IF(N18<M18,"날짜 확인",NETWORKDAYS(M18,N18,휴일!$A$2:$A$2))) -> 2 | Q18: =IF(O18="","",IF($L$1<K18,0,NETWORKDAYS(K18,MIN($L$1,L18),휴일!$A$2:$A$2))) -> 1 | R18: =IF(M18="","",IF($L$1<M18,0,NETWORKDAYS(M18,IF(N18="",$L$1,MIN($L$1,N18)),휴일!$A$2:$A$2))) -> 2 | S18: =IF(O18="","",IF(O18=0,0,Q18/O18)) -> 1 | T18: =IF(OR(AND(AG18<>"",OR(NOT(ISNUMBER(AG18)),AG18<=0)),AND(AH18<>"",OR(NOT(ISNUMBER(AH18)),AH18<0)),AND(ISNUMBER(AG18),ISNUMBER(AH18),AH18>AG18)),"수량 확인",IF(AF18="완료",1,IF(AF18="미착수",0,IF(AND(ISNUMBER(AG18),ISNUMBER(AH18)),AH18/AG18,"")))) -> 1 | U18: =IF(T18="","",T18) -> 1 | V18: =IF(OR(U18="",S18=""),"",U18-S18) -> 0 | W18: =IF(AND(ISNUMBER($M18),W$5>=$M18,W$5<=IF($N18="",$L$1,$N18),WEEKDAY(W$5,2)<6,COUNTIF(휴일!$A$2:$A$2,W$5)=0),2,IF(AND(ISNUMBER($K18),W$5>=$K18,W$5<=$L18,WEEKDAY(W$5,2)<6,COUNTIF(휴일!$A$2:$A$2,W$5)=0),1,"")) | X18: =IF(AND(ISNUMBER($M18),X$5>=$M18,X$5<=IF($N18="",$L$1,$N18),WEEKDAY(X$5,2)<6,COUNTIF(휴일!$A$2:$A$2,X$5)=0),2,IF(AND(ISNUMBER($K18),X$5>=$K18,X$5<=$L18,WEEKDAY(X$5,2)<6,COUNTIF(휴일!$A$2:$A$2,X$5)=0),1,"")) -> 1 | Y18: =IF(AND(ISNUMBER($M18),Y$5>=$M18,Y$5<=IF($N18="",$L$1,$N18),WEEKDAY(Y$5,2)<6,COUNTIF(휴일!$A$2:$A$2,Y$5)=0),2,IF(AND(ISNUMBER($K18),Y$5>=$K18,Y$5<=$L18,WEEKDAY(Y$5,2)<6,COUNTIF(휴일!$A$2:$A$2,Y$5)=0),1,"")) -> 2 | Z18: =IF(AND(ISNUMBER($M18),Z$5>=$M18,Z$5<=IF($N18="",$L$1,$N18),WEEKDAY(Z$5,2)<6,COUNTIF(휴일!$A$2:$A$2,Z$5)=0),2,IF(AND(ISNUMBER($K18),Z$5>=$K18,Z$5<=$L18,WEEKDAY(Z$5,2)<6,COUNTIF(휴일!$A$2:$A$2,Z$5)=0),1,"")) | AA18: =IF(AND(ISNUMBER($M18),AA$5>=$M18,AA$5<=IF($N18="",$L$1,$N18),WEEKDAY(AA$5,2)<6,COUNTIF(휴일!$A$2:$A$2,AA$5)=0),2,IF(AND(ISNUMBER($K18),AA$5>=$K18,AA$5<=$L18,WEEKDAY(AA$5,2)<6,COUNTIF(휴일!$A$2:$A$2,AA$5)=0),1,"")) | AB18: =IF(AND(ISNUMBER($M18),AB$5>=$M18,AB$5<=IF($N18="",$L$1,$N18),WEEKDAY(AB$5,2)<6,COUNTIF(휴일!$A$2:$A$2,AB$5)=0),2,IF(AND(ISNUMBER($K18),AB$5>=$K18,AB$5<=$L18,WEEKDAY(AB$5,2)<6,COUNTIF(휴일!$A$2:$A$2,AB$5)=0),1,"")) | AC18: =IF(AND(ISNUMBER($M18),AC$5>=$M18,AC$5<=IF($N18="",$L$1,$N18),WEEKDAY(AC$5,2)<6,COUNTIF(휴일!$A$2:$A$2,AC$5)=0),2,IF(AND(ISNUMBER($K18),AC$5>=$K18,AC$5<=$L18,WEEKDAY(AC$5,2)<6,COUNTIF(휴일!$A$2:$A$2,AC$5)=0),1,"")) -> 2 | AD18: =IF(AND(ISNUMBER($M18),AD$5>=$M18,AD$5<=IF($N18="",$L$1,$N18),WEEKDAY(AD$5,2)<6,COUNTIF(휴일!$A$2:$A$2,AD$5)=0),2,IF(AND(ISNUMBER($K18),AD$5>=$K18,AD$5<=$L18,WEEKDAY(AD$5,2)<6,COUNTIF(휴일!$A$2:$A$2,AD$5)=0),1,"")) | AE18: =IF(AND(ISNUMBER($M18),AE$5>=$M18,AE$5<=IF($N18="",$L$1,$N18),WEEKDAY(AE$5,2)<6,COUNTIF(휴일!$A$2:$A$2,AE$5)=0),2,IF(AND(ISNUMBER($K18),AE$5>=$K18,AE$5<=$L18,WEEKDAY(AE$5,2)<6,COUNTIF(휴일!$A$2:$A$2,AE$5)=0),1,"")) | AF18: 완료
F19: 2.09 HomeEvents 발행·구독 구현 | H19: 김찬중 | I19: 권오민 | J19: NFR-05 입퇴실·옵션·시간·로봇 이벤트 형식 통일 | K19: 46302 | L19: 46302 | M19: 46302 | N19: 46302 | O19: =IF(OR(K19="",L19=""),"",IF(L19<K19,"날짜 확인",NETWORKDAYS(K19,L19,휴일!$A$2:$A$2))) -> 1 | P19: =IF(OR(M19="",N19=""),"",IF(N19<M19,"날짜 확인",NETWORKDAYS(M19,N19,휴일!$A$2:$A$2))) -> 1 | Q19: =IF(O19="","",IF($L$1<K19,0,NETWORKDAYS(K19,MIN($L$1,L19),휴일!$A$2:$A$2))) -> 1 | R19: =IF(M19="","",IF($L$1<M19,0,NETWORKDAYS(M19,IF(N19="",$L$1,MIN($L$1,N19)),휴일!$A$2:$A$2))) -> 1 | S19: =IF(O19="","",IF(O19=0,0,Q19/O19)) -> 1 | T19: =IF(OR(AND(AG19<>"",OR(NOT(ISNUMBER(AG19)),AG19<=0)),AND(AH19<>"",OR(NOT(ISNUMBER(AH19)),AH19<0)),AND(ISNUMBER(AG19),ISNUMBER(AH19),AH19>AG19)),"수량 확인",IF(AF19="완료",1,IF(AF19="미착수",0,IF(AND(ISNUMBER(AG19),ISNUMBER(AH19)),AH19/AG19,"")))) -> 1 | U19: =IF(T19="","",T19) -> 1 | V19: =IF(OR(U19="",S19=""),"",U19-S19) -> 0 | W19: =IF(AND(ISNUMBER($M19),W$5>=$M19,W$5<=IF($N19="",$L$1,$N19),WEEKDAY(W$5,2)<6,COUNTIF(휴일!$A$2:$A$2,W$5)=0),2,IF(AND(ISNUMBER($K19),W$5>=$K19,W$5<=$L19,WEEKDAY(W$5,2)<6,COUNTIF(휴일!$A$2:$A$2,W$5)=0),1,"")) | X19: =IF(AND(ISNUMBER($M19),X$5>=$M19,X$5<=IF($N19="",$L$1,$N19),WEEKDAY(X$5,2)<6,COUNTIF(휴일!$A$2:$A$2,X$5)=0),2,IF(AND(ISNUMBER($K19),X$5>=$K19,X$5<=$L19,WEEKDAY(X$5,2)<6,COUNTIF(휴일!$A$2:$A$2,X$5)=0),1,"")) -> 2 | Y19: =IF(AND(ISNUMBER($M19),Y$5>=$M19,Y$5<=IF($N19="",$L$1,$N19),WEEKDAY(Y$5,2)<6,COUNTIF(휴일!$A$2:$A$2,Y$5)=0),2,IF(AND(ISNUMBER($K19),Y$5>=$K19,Y$5<=$L19,WEEKDAY(Y$5,2)<6,COUNTIF(휴일!$A$2:$A$2,Y$5)=0),1,"")) | Z19: =IF(AND(ISNUMBER($M19),Z$5>=$M19,Z$5<=IF($N19="",$L$1,$N19),WEEKDAY(Z$5,2)<6,COUNTIF(휴일!$A$2:$A$2,Z$5)=0),2,IF(AND(ISNUMBER($K19),Z$5>=$K19,Z$5<=$L19,WEEKDAY(Z$5,2)<6,COUNTIF(휴일!$A$2:$A$2,Z$5)=0),1,"")) | AA19: =IF(AND(ISNUMBER($M19),AA$5>=$M19,AA$5<=IF($N19="",$L$1,$N19),WEEKDAY(AA$5,2)<6,COUNTIF(휴일!$A$2:$A$2,AA$5)=0),2,IF(AND(ISNUMBER($K19),AA$5>=$K19,AA$5<=$L19,WEEKDAY(AA$5,2)<6,COUNTIF(휴일!$A$2:$A$2,AA$5)=0),1,"")) | AB19: =IF(AND(ISNUMBER($M19),AB$5>=$M19,AB$5<=IF($N19="",$L$1,$N19),WEEKDAY(AB$5,2)<6,COUNTIF(휴일!$A$2:$A$2,AB$5)=0),2,IF(AND(ISNUMBER($K19),AB$5>=$K19,AB$5<=$L19,WEEKDAY(AB$5,2)<6,COUNTIF(휴일!$A$2:$A$2,AB$5)=0),1,"")) | AC19: =IF(AND(ISNUMBER($M19),AC$5>=$M19,AC$5<=IF($N19="",$L$1,$N19),WEEKDAY(AC$5,2)<6,COUNTIF(휴일!$A$2:$A$2,AC$5)=0),2,IF(AND(ISNUMBER($K19),AC$5>=$K19,AC$5<=$L19,WEEKDAY(AC$5,2)<6,COUNTIF(휴일!$A$2:$A$2,AC$5)=0),1,"")) | AD19: =IF(AND(ISNUMBER($M19),AD$5>=$M19,AD$5<=IF($N19="",$L$1,$N19),WEEKDAY(AD$5,2)<6,COUNTIF(휴일!$A$2:$A$2,AD$5)=0),2,IF(AND(ISNUMBER($K19),AD$5>=$K19,AD$5<=$L19,WEEKDAY(AD$5,2)<6,COUNTIF(휴일!$A$2:$A$2,AD$5)=0),1,"")) | AE19: =IF(AND(ISNUMBER($M19),AE$5>=$M19,AE$5<=IF($N19="",$L$1,$N19),WEEKDAY(AE$5,2)<6,COUNTIF(휴일!$A$2:$A$2,AE$5)=0),2,IF(AND(ISNUMBER($K19),AE$5>=$K19,AE$5<=$L19,WEEKDAY(AE$5,2)<6,COUNTIF(휴일!$A$2:$A$2,AE$5)=0),1,"")) | AF19: 완료
F20: 2.10 URP 기본 조명·프로브 배치 | H20: 권오민 | I20: 김찬중 | J20: NFR-10 Forward+ 및 구역별 반사 프로브 구성 거울 프로브 Custom 유지·중복 정리 (10/12) | K20: 46302 | L20: 46302 | M20: 46303 | N20: 46307 | O20: =IF(OR(K20="",L20=""),"",IF(L20<K20,"날짜 확인",NETWORKDAYS(K20,L20,휴일!$A$2:$A$2))) -> 1 | P20: =IF(OR(M20="",N20=""),"",IF(N20<M20,"날짜 확인",NETWORKDAYS(M20,N20,휴일!$A$2:$A$2))) -> 2 | Q20: =IF(O20="","",IF($L$1<K20,0,NETWORKDAYS(K20,MIN($L$1,L20),휴일!$A$2:$A$2))) -> 1 | R20: =IF(M20="","",IF($L$1<M20,0,NETWORKDAYS(M20,IF(N20="",$L$1,MIN($L$1,N20)),휴일!$A$2:$A$2))) -> 2 | S20: =IF(O20="","",IF(O20=0,0,Q20/O20)) -> 1 | T20: =IF(OR(AND(AG20<>"",OR(NOT(ISNUMBER(AG20)),AG20<=0)),AND(AH20<>"",OR(NOT(ISNUMBER(AH20)),AH20<0)),AND(ISNUMBER(AG20),ISNUMBER(AH20),AH20>AG20)),"수량 확인",IF(AF20="완료",1,IF(AF20="미착수",0,IF(AND(ISNUMBER(AG20),ISNUMBER(AH20)),AH20/AG20,"")))) -> 1 | U20: =IF(T20="","",T20) -> 1 | V20: =IF(OR(U20="",S20=""),"",U20-S20) -> 0 | W20: =IF(AND(ISNUMBER($M20),W$5>=$M20,W$5<=IF($N20="",$L$1,$N20),WEEKDAY(W$5,2)<6,COUNTIF(휴일!$A$2:$A$2,W$5)=0),2,IF(AND(ISNUMBER($K20),W$5>=$K20,W$5<=$L20,WEEKDAY(W$5,2)<6,COUNTIF(휴일!$A$2:$A$2,W$5)=0),1,"")) | X20: =IF(AND(ISNUMBER($M20),X$5>=$M20,X$5<=IF($N20="",$L$1,$N20),WEEKDAY(X$5,2)<6,COUNTIF(휴일!$A$2:$A$2,X$5)=0),2,IF(AND(ISNUMBER($K20),X$5>=$K20,X$5<=$L20,WEEKDAY(X$5,2)<6,COUNTIF(휴일!$A$2:$A$2,X$5)=0),1,"")) -> 1 | Y20: =IF(AND(ISNUMBER($M20),Y$5>=$M20,Y$5<=IF($N20="",$L$1,$N20),WEEKDAY(Y$5,2)<6,COUNTIF(휴일!$A$2:$A$2,Y$5)=0),2,IF(AND(ISNUMBER($K20),Y$5>=$K20,Y$5<=$L20,WEEKDAY(Y$5,2)<6,COUNTIF(휴일!$A$2:$A$2,Y$5)=0),1,"")) -> 2 | Z20: =IF(AND(ISNUMBER($M20),Z$5>=$M20,Z$5<=IF($N20="",$L$1,$N20),WEEKDAY(Z$5,2)<6,COUNTIF(휴일!$A$2:$A$2,Z$5)=0),2,IF(AND(ISNUMBER($K20),Z$5>=$K20,Z$5<=$L20,WEEKDAY(Z$5,2)<6,COUNTIF(휴일!$A$2:$A$2,Z$5)=0),1,"")) | AA20: =IF(AND(ISNUMBER($M20),AA$5>=$M20,AA$5<=IF($N20="",$L$1,$N20),WEEKDAY(AA$5,2)<6,COUNTIF(휴일!$A$2:$A$2,AA$5)=0),2,IF(AND(ISNUMBER($K20),AA$5>=$K20,AA$5<=$L20,WEEKDAY(AA$5,2)<6,COUNTIF(휴일!$A$2:$A$2,AA$5)=0),1,"")) | AB20: =IF(AND(ISNUMBER($M20),AB$5>=$M20,AB$5<=IF($N20="",$L$1,$N20),WEEKDAY(AB$5,2)<6,COUNTIF(휴일!$A$2:$A$2,AB$5)=0),2,IF(AND(ISNUMBER($K20),AB$5>=$K20,AB$5<=$L20,WEEKDAY(AB$5,2)<6,COUNTIF(휴일!$A$2:$A$2,AB$5)=0),1,"")) | AC20: =IF(AND(ISNUMBER($M20),AC$5>=$M20,AC$5<=IF($N20="",$L$1,$N20),WEEKDAY(AC$5,2)<6,COUNTIF(휴일!$A$2:$A$2,AC$5)=0),2,IF(AND(ISNUMBER($K20),AC$5>=$K20,AC$5<=$L20,WEEKDAY(AC$5,2)<6,COUNTIF(휴일!$A$2:$A$2,AC$5)=0),1,"")) -> 2 | AD20: =IF(AND(ISNUMBER($M20),AD$5>=$M20,AD$5<=IF($N20="",$L$1,$N20),WEEKDAY(AD$5,2)<6,COUNTIF(휴일!$A$2:$A$2,AD$5)=0),2,IF(AND(ISNUMBER($K20),AD$5>=$K20,AD$5<=$L20,WEEKDAY(AD$5,2)<6,COUNTIF(휴일!$A$2:$A$2,AD$5)=0),1,"")) | AE20: =IF(AND(ISNUMBER($M20),AE$5>=$M20,AE$5<=IF($N20="",$L$1,$N20),WEEKDAY(AE$5,2)<6,COUNTIF(휴일!$A$2:$A$2,AE$5)=0),2,IF(AND(ISNUMBER($K20),AE$5>=$K20,AE$5<=$L20,WEEKDAY(AE$5,2)<6,COUNTIF(휴일!$A$2:$A$2,AE$5)=0),1,"")) | AF20: 완료
F21: 2.11 첫날 프리팹 전달·Main 통합 | H21: 권오민 | I21: 김찬중 | J21: 관리 Main 실행 오류 없음, 누락 참조 확인 | K21: 46302 | L21: 46302 | M21: 46303 | N21: 46303 | O21: =IF(OR(K21="",L21=""),"",IF(L21<K21,"날짜 확인",NETWORKDAYS(K21,L21,휴일!$A$2:$A$2))) -> 1 | P21: =IF(OR(M21="",N21=""),"",IF(N21<M21,"날짜 확인",NETWORKDAYS(M21,N21,휴일!$A$2:$A$2))) -> 1 | Q21: =IF(O21="","",IF($L$1<K21,0,NETWORKDAYS(K21,MIN($L$1,L21),휴일!$A$2:$A$2))) -> 1 | R21: =IF(M21="","",IF($L$1<M21,0,NETWORKDAYS(M21,IF(N21="",$L$1,MIN($L$1,N21)),휴일!$A$2:$A$2))) -> 1 | S21: =IF(O21="","",IF(O21=0,0,Q21/O21)) -> 1 | T21: =IF(OR(AND(AG21<>"",OR(NOT(ISNUMBER(AG21)),AG21<=0)),AND(AH21<>"",OR(NOT(ISNUMBER(AH21)),AH21<0)),AND(ISNUMBER(AG21),ISNUMBER(AH21),AH21>AG21)),"수량 확인",IF(AF21="완료",1,IF(AF21="미착수",0,IF(AND(ISNUMBER(AG21),ISNUMBER(AH21)),AH21/AG21,"")))) -> 1 | U21: =IF(T21="","",T21) -> 1 | V21: =IF(OR(U21="",S21=""),"",U21-S21) -> 0 | W21: =IF(AND(ISNUMBER($M21),W$5>=$M21,W$5<=IF($N21="",$L$1,$N21),WEEKDAY(W$5,2)<6,COUNTIF(휴일!$A$2:$A$2,W$5)=0),2,IF(AND(ISNUMBER($K21),W$5>=$K21,W$5<=$L21,WEEKDAY(W$5,2)<6,COUNTIF(휴일!$A$2:$A$2,W$5)=0),1,"")) | X21: =IF(AND(ISNUMBER($M21),X$5>=$M21,X$5<=IF($N21="",$L$1,$N21),WEEKDAY(X$5,2)<6,COUNTIF(휴일!$A$2:$A$2,X$5)=0),2,IF(AND(ISNUMBER($K21),X$5>=$K21,X$5<=$L21,WEEKDAY(X$5,2)<6,COUNTIF(휴일!$A$2:$A$2,X$5)=0),1,"")) -> 1 | Y21: =IF(AND(ISNUMBER($M21),Y$5>=$M21,Y$5<=IF($N21="",$L$1,$N21),WEEKDAY(Y$5,2)<6,COUNTIF(휴일!$A$2:$A$2,Y$5)=0),2,IF(AND(ISNUMBER($K21),Y$5>=$K21,Y$5<=$L21,WEEKDAY(Y$5,2)<6,COUNTIF(휴일!$A$2:$A$2,Y$5)=0),1,"")) -> 2 | Z21: =IF(AND(ISNUMBER($M21),Z$5>=$M21,Z$5<=IF($N21="",$L$1,$N21),WEEKDAY(Z$5,2)<6,COUNTIF(휴일!$A$2:$A$2,Z$5)=0),2,IF(AND(ISNUMBER($K21),Z$5>=$K21,Z$5<=$L21,WEEKDAY(Z$5,2)<6,COUNTIF(휴일!$A$2:$A$2,Z$5)=0),1,"")) | AA21: =IF(AND(ISNUMBER($M21),AA$5>=$M21,AA$5<=IF($N21="",$L$1,$N21),WEEKDAY(AA$5,2)<6,COUNTIF(휴일!$A$2:$A$2,AA$5)=0),2,IF(AND(ISNUMBER($K21),AA$5>=$K21,AA$5<=$L21,WEEKDAY(AA$5,2)<6,COUNTIF(휴일!$A$2:$A$2,AA$5)=0),1,"")) | AB21: =IF(AND(ISNUMBER($M21),AB$5>=$M21,AB$5<=IF($N21="",$L$1,$N21),WEEKDAY(AB$5,2)<6,COUNTIF(휴일!$A$2:$A$2,AB$5)=0),2,IF(AND(ISNUMBER($K21),AB$5>=$K21,AB$5<=$L21,WEEKDAY(AB$5,2)<6,COUNTIF(휴일!$A$2:$A$2,AB$5)=0),1,"")) | AC21: =IF(AND(ISNUMBER($M21),AC$5>=$M21,AC$5<=IF($N21="",$L$1,$N21),WEEKDAY(AC$5,2)<6,COUNTIF(휴일!$A$2:$A$2,AC$5)=0),2,IF(AND(ISNUMBER($K21),AC$5>=$K21,AC$5<=$L21,WEEKDAY(AC$5,2)<6,COUNTIF(휴일!$A$2:$A$2,AC$5)=0),1,"")) | AD21: =IF(AND(ISNUMBER($M21),AD$5>=$M21,AD$5<=IF($N21="",$L$1,$N21),WEEKDAY(AD$5,2)<6,COUNTIF(휴일!$A$2:$A$2,AD$5)=0),2,IF(AND(ISNUMBER($K21),AD$5>=$K21,AD$5<=$L21,WEEKDAY(AD$5,2)<6,COUNTIF(휴일!$A$2:$A$2,AD$5)=0),1,"")) | AE21: =IF(AND(ISNUMBER($M21),AE$5>=$M21,AE$5<=IF($N21="",$L$1,$N21),WEEKDAY(AE$5,2)<6,COUNTIF(휴일!$A$2:$A$2,AE$5)=0),2,IF(AND(ISNUMBER($K21),AE$5>=$K21,AE$5<=$L21,WEEKDAY(AE$5,2)<6,COUNTIF(휴일!$A$2:$A$2,AE$5)=0),1,"")) | AF21: 완료
F22: 2.12 첫날 PR 검토·로그 점검 | H22: 김찬중 | I22: 권오민 | J22: 관리 리뷰 완료, 19시 이전 통합·다음 작업 공유 | K22: 46302 | L22: 46302 | M22: 46303 | N22: 46303 | O22: =IF(OR(K22="",L22=""),"",IF(L22<K22,"날짜 확인",NETWORKDAYS(K22,L22,휴일!$A$2:$A$2))) -> 1 | P22: =IF(OR(M22="",N22=""),"",IF(N22<M22,"날짜 확인",NETWORKDAYS(M22,N22,휴일!$A$2:$A$2))) -> 1 | Q22: =IF(O22="","",IF($L$1<K22,0,NETWORKDAYS(K22,MIN($L$1,L22),휴일!$A$2:$A$2))) -> 1 | R22: =IF(M22="","",IF($L$1<M22,0,NETWORKDAYS(M22,IF(N22="",$L$1,MIN($L$1,N22)),휴일!$A$2:$A$2))) -> 1 | S22: =IF(O22="","",IF(O22=0,0,Q22/O22)) -> 1 | T22: =IF(OR(AND(AG22<>"",OR(NOT(ISNUMBER(AG22)),AG22<=0)),AND(AH22<>"",OR(NOT(ISNUMBER(AH22)),AH22<0)),AND(ISNUMBER(AG22),ISNUMBER(AH22),AH22>AG22)),"수량 확인",IF(AF22="완료",1,IF(AF22="미착수",0,IF(AND(ISNUMBER(AG22),ISNUMBER(AH22)),AH22/AG22,"")))) -> 1 | U22: =IF(T22="","",T22) -> 1 | V22: =IF(OR(U22="",S22=""),"",U22-S22) -> 0 | W22: =IF(AND(ISNUMBER($M22),W$5>=$M22,W$5<=IF($N22="",$L$1,$N22),WEEKDAY(W$5,2)<6,COUNTIF(휴일!$A$2:$A$2,W$5)=0),2,IF(AND(ISNUMBER($K22),W$5>=$K22,W$5<=$L22,WEEKDAY(W$5,2)<6,COUNTIF(휴일!$A$2:$A$2,W$5)=0),1,"")) | X22: =IF(AND(ISNUMBER($M22),X$5>=$M22,X$5<=IF($N22="",$L$1,$N22),WEEKDAY(X$5,2)<6,COUNTIF(휴일!$A$2:$A$2,X$5)=0),2,IF(AND(ISNUMBER($K22),X$5>=$K22,X$5<=$L22,WEEKDAY(X$5,2)<6,COUNTIF(휴일!$A$2:$A$2,X$5)=0),1,"")) -> 1 | Y22: =IF(AND(ISNUMBER($M22),Y$5>=$M22,Y$5<=IF($N22="",$L$1,$N22),WEEKDAY(Y$5,2)<6,COUNTIF(휴일!$A$2:$A$2,Y$5)=0),2,IF(AND(ISNUMBER($K22),Y$5>=$K22,Y$5<=$L22,WEEKDAY(Y$5,2)<6,COUNTIF(휴일!$A$2:$A$2,Y$5)=0),1,"")) -> 2 | Z22: =IF(AND(ISNUMBER($M22),Z$5>=$M22,Z$5<=IF($N22="",$L$1,$N22),WEEKDAY(Z$5,2)<6,COUNTIF(휴일!$A$2:$A$2,Z$5)=0),2,IF(AND(ISNUMBER($K22),Z$5>=$K22,Z$5<=$L22,WEEKDAY(Z$5,2)<6,COUNTIF(휴일!$A$2:$A$2,Z$5)=0),1,"")) | AA22: =IF(AND(ISNUMBER($M22),AA$5>=$M22,AA$5<=IF($N22="",$L$1,$N22),WEEKDAY(AA$5,2)<6,COUNTIF(휴일!$A$2:$A$2,AA$5)=0),2,IF(AND(ISNUMBER($K22),AA$5>=$K22,AA$5<=$L22,WEEKDAY(AA$5,2)<6,COUNTIF(휴일!$A$2:$A$2,AA$5)=0),1,"")) | AB22: =IF(AND(ISNUMBER($M22),AB$5>=$M22,AB$5<=IF($N22="",$L$1,$N22),WEEKDAY(AB$5,2)<6,COUNTIF(휴일!$A$2:$A$2,AB$5)=0),2,IF(AND(ISNUMBER($K22),AB$5>=$K22,AB$5<=$L22,WEEKDAY(AB$5,2)<6,COUNTIF(휴일!$A$2:$A$2,AB$5)=0),1,"")) | AC22: =IF(AND(ISNUMBER($M22),AC$5>=$M22,AC$5<=IF($N22="",$L$1,$N22),WEEKDAY(AC$5,2)<6,COUNTIF(휴일!$A$2:$A$2,AC$5)=0),2,IF(AND(ISNUMBER($K22),AC$5>=$K22,AC$5<=$L22,WEEKDAY(AC$5,2)<6,COUNTIF(휴일!$A$2:$A$2,AC$5)=0),1,"")) | AD22: =IF(AND(ISNUMBER($M22),AD$5>=$M22,AD$5<=IF($N22="",$L$1,$N22),WEEKDAY(AD$5,2)<6,COUNTIF(휴일!$A$2:$A$2,AD$5)=0),2,IF(AND(ISNUMBER($K22),AD$5>=$K22,AD$5<=$L22,WEEKDAY(AD$5,2)<6,COUNTIF(휴일!$A$2:$A$2,AD$5)=0),1,"")) | AE22: =IF(AND(ISNUMBER($M22),AE$5>=$M22,AE$5<=IF($N22="",$L$1,$N22),WEEKDAY(AE$5,2)<6,COUNTIF(휴일!$A$2:$A$2,AE$5)=0),2,IF(AND(ISNUMBER($K22),AE$5>=$K22,AE$5<=$L22,WEEKDAY(AE$5,2)<6,COUNTIF(휴일!$A$2:$A$2,AE$5)=0),1,"")) | AF22: 완료
B23: 3 | C23: 0.20247934 | D23: 기능 구현 1 | F23: 3.01 WASD 이동·카메라 높이 구현 | H23: 권오민 | I23: 김찬중 | J23: FR-01 높이1.6m, 바라보는 방향 기준 이동 | K23: 46303 | L23: 46303 | M23: 46303 | N23: 46303 | O23: =IF(OR(K23="",L23=""),"",IF(L23<K23,"날짜 확인",NETWORKDAYS(K23,L23,휴일!$A$2:$A$2))) -> 1 | P23: =IF(OR(M23="",N23=""),"",IF(N23<M23,"날짜 확인",NETWORKDAYS(M23,N23,휴일!$A$2:$A$2))) -> 1 | Q23: =IF(O23="","",IF($L$1<K23,0,NETWORKDAYS(K23,MIN($L$1,L23),휴일!$A$2:$A$2))) -> 1 | R23: =IF(M23="","",IF($L$1<M23,0,NETWORKDAYS(M23,IF(N23="",$L$1,MIN($L$1,N23)),휴일!$A$2:$A$2))) -> 1 | S23: =IF(O23="","",IF(O23=0,0,Q23/O23)) -> 1 | T23: =IF(OR(AND(AG23<>"",OR(NOT(ISNUMBER(AG23)),AG23<=0)),AND(AH23<>"",OR(NOT(ISNUMBER(AH23)),AH23<0)),AND(ISNUMBER(AG23),ISNUMBER(AH23),AH23>AG23)),"수량 확인",IF(AF23="완료",1,IF(AF23="미착수",0,IF(AND(ISNUMBER(AG23),ISNUMBER(AH23)),AH23/AG23,"")))) -> 1 | U23: =IF(T23="","",T23) -> 1 | V23: =IF(OR(U23="",S23=""),"",U23-S23) -> 0 | W23: =IF(AND(ISNUMBER($M23),W$5>=$M23,W$5<=IF($N23="",$L$1,$N23),WEEKDAY(W$5,2)<6,COUNTIF(휴일!$A$2:$A$2,W$5)=0),2,IF(AND(ISNUMBER($K23),W$5>=$K23,W$5<=$L23,WEEKDAY(W$5,2)<6,COUNTIF(휴일!$A$2:$A$2,W$5)=0),1,"")) | X23: =IF(AND(ISNUMBER($M23),X$5>=$M23,X$5<=IF($N23="",$L$1,$N23),WEEKDAY(X$5,2)<6,COUNTIF(휴일!$A$2:$A$2,X$5)=0),2,IF(AND(ISNUMBER($K23),X$5>=$K23,X$5<=$L23,WEEKDAY(X$5,2)<6,COUNTIF(휴일!$A$2:$A$2,X$5)=0),1,"")) | Y23: =IF(AND(ISNUMBER($M23),Y$5>=$M23,Y$5<=IF($N23="",$L$1,$N23),WEEKDAY(Y$5,2)<6,COUNTIF(휴일!$A$2:$A$2,Y$5)=0),2,IF(AND(ISNUMBER($K23),Y$5>=$K23,Y$5<=$L23,WEEKDAY(Y$5,2)<6,COUNTIF(휴일!$A$2:$A$2,Y$5)=0),1,"")) -> 2 | Z23: =IF(AND(ISNUMBER($M23),Z$5>=$M23,Z$5<=IF($N23="",$L$1,$N23),WEEKDAY(Z$5,2)<6,COUNTIF(휴일!$A$2:$A$2,Z$5)=0),2,IF(AND(ISNUMBER($K23),Z$5>=$K23,Z$5<=$L23,WEEKDAY(Z$5,2)<6,COUNTIF(휴일!$A$2:$A$2,Z$5)=0),1,"")) | AA23: =IF(AND(ISNUMBER($M23),AA$5>=$M23,AA$5<=IF($N23="",$L$1,$N23),WEEKDAY(AA$5,2)<6,COUNTIF(휴일!$A$2:$A$2,AA$5)=0),2,IF(AND(ISNUMBER($K23),AA$5>=$K23,AA$5<=$L23,WEEKDAY(AA$5,2)<6,COUNTIF(휴일!$A$2:$A$2,AA$5)=0),1,"")) | AB23: =IF(AND(ISNUMBER($M23),AB$5>=$M23,AB$5<=IF($N23="",$L$1,$N23),WEEKDAY(AB$5,2)<6,COUNTIF(휴일!$A$2:$A$2,AB$5)=0),2,IF(AND(ISNUMBER($K23),AB$5>=$K23,AB$5<=$L23,WEEKDAY(AB$5,2)<6,COUNTIF(휴일!$A$2:$A$2,AB$5)=0),1,"")) | AC23: =IF(AND(ISNUMBER($M23),AC$5>=$M23,AC$5<=IF($N23="",$L$1,$N23),WEEKDAY(AC$5,2)<6,COUNTIF(휴일!$A$2:$A$2,AC$5)=0),2,IF(AND(ISNUMBER($K23),AC$5>=$K23,AC$5<=$L23,WEEKDAY(AC$5,2)<6,COUNTIF(휴일!$A$2:$A$2,AC$5)=0),1,"")) | AD23: =IF(AND(ISNUMBER($M23),AD$5>=$M23,AD$5<=IF($N23="",$L$1,$N23),WEEKDAY(AD$5,2)<6,COUNTIF(휴일!$A$2:$A$2,AD$5)=0),2,IF(AND(ISNUMBER($K23),AD$5>=$K23,AD$5<=$L23,WEEKDAY(AD$5,2)<6,COUNTIF(휴일!$A$2:$A$2,AD$5)=0),1,"")) | AE23: =IF(AND(ISNUMBER($M23),AE$5>=$M23,AE$5<=IF($N23="",$L$1,$N23),WEEKDAY(AE$5,2)<6,COUNTIF(휴일!$A$2:$A$2,AE$5)=0),2,IF(AND(ISNUMBER($K23),AE$5>=$K23,AE$5<=$L23,WEEKDAY(AE$5,2)<6,COUNTIF(휴일!$A$2:$A$2,AE$5)=0),1,"")) | AF23: 완료
F24: 3.02 우클릭 시점·커서·UI 입력 분리 | H24: 권오민 | I24: 김찬중 | J24: FR-01 우클릭 때만 회전, 커서 표시, UI 위 회전 방지 | K24: 46303 | L24: 46303 | M24: 46303 | N24: 46303 | O24: =IF(OR(K24="",L24=""),"",IF(L24<K24,"날짜 확인",NETWORKDAYS(K24,L24,휴일!$A$2:$A$2))) -> 1 | P24: =IF(OR(M24="",N24=""),"",IF(N24<M24,"날짜 확인",NETWORKDAYS(M24,N24,휴일!$A$2:$A$2))) -> 1 | Q24: =IF(O24="","",IF($L$1<K24,0,NETWORKDAYS(K24,MIN($L$1,L24),휴일!$A$2:$A$2))) -> 1 | R24: =IF(M24="","",IF($L$1<M24,0,NETWORKDAYS(M24,IF(N24="",$L$1,MIN($L$1,N24)),휴일!$A$2:$A$2))) -> 1 | S24: =IF(O24="","",IF(O24=0,0,Q24/O24)) -> 1 | T24: =IF(OR(AND(AG24<>"",OR(NOT(ISNUMBER(AG24)),AG24<=0)),AND(AH24<>"",OR(NOT(ISNUMBER(AH24)),AH24<0)),AND(ISNUMBER(AG24),ISNUMBER(AH24),AH24>AG24)),"수량 확인",IF(AF24="완료",1,IF(AF24="미착수",0,IF(AND(ISNUMBER(AG24),ISNUMBER(AH24)),AH24/AG24,"")))) -> 1 | U24: =IF(T24="","",T24) -> 1 | V24: =IF(OR(U24="",S24=""),"",U24-S24) -> 0 | W24: =IF(AND(ISNUMBER($M24),W$5>=$M24,W$5<=IF($N24="",$L$1,$N24),WEEKDAY(W$5,2)<6,COUNTIF(휴일!$A$2:$A$2,W$5)=0),2,IF(AND(ISNUMBER($K24),W$5>=$K24,W$5<=$L24,WEEKDAY(W$5,2)<6,COUNTIF(휴일!$A$2:$A$2,W$5)=0),1,"")) | X24: =IF(AND(ISNUMBER($M24),X$5>=$M24,X$5<=IF($N24="",$L$1,$N24),WEEKDAY(X$5,2)<6,COUNTIF(휴일!$A$2:$A$2,X$5)=0),2,IF(AND(ISNUMBER($K24),X$5>=$K24,X$5<=$L24,WEEKDAY(X$5,2)<6,COUNTIF(휴일!$A$2:$A$2,X$5)=0),1,"")) | Y24: =IF(AND(ISNUMBER($M24),Y$5>=$M24,Y$5<=IF($N24="",$L$1,$N24),WEEKDAY(Y$5,2)<6,COUNTIF(휴일!$A$2:$A$2,Y$5)=0),2,IF(AND(ISNUMBER($K24),Y$5>=$K24,Y$5<=$L24,WEEKDAY(Y$5,2)<6,COUNTIF(휴일!$A$2:$A$2,Y$5)=0),1,"")) -> 2 | Z24: =IF(AND(ISNUMBER($M24),Z$5>=$M24,Z$5<=IF($N24="",$L$1,$N24),WEEKDAY(Z$5,2)<6,COUNTIF(휴일!$A$2:$A$2,Z$5)=0),2,IF(AND(ISNUMBER($K24),Z$5>=$K24,Z$5<=$L24,WEEKDAY(Z$5,2)<6,COUNTIF(휴일!$A$2:$A$2,Z$5)=0),1,"")) | AA24: =IF(AND(ISNUMBER($M24),AA$5>=$M24,AA$5<=IF($N24="",$L$1,$N24),WEEKDAY(AA$5,2)<6,COUNTIF(휴일!$A$2:$A$2,AA$5)=0),2,IF(AND(ISNUMBER($K24),AA$5>=$K24,AA$5<=$L24,WEEKDAY(AA$5,2)<6,COUNTIF(휴일!$A$2:$A$2,AA$5)=0),1,"")) | AB24: =IF(AND(ISNUMBER($M24),AB$5>=$M24,AB$5<=IF($N24="",$L$1,$N24),WEEKDAY(AB$5,2)<6,COUNTIF(휴일!$A$2:$A$2,AB$5)=0),2,IF(AND(ISNUMBER($K24),AB$5>=$K24,AB$5<=$L24,WEEKDAY(AB$5,2)<6,COUNTIF(휴일!$A$2:$A$2,AB$5)=0),1,"")) | AC24: =IF(AND(ISNUMBER($M24),AC$5>=$M24,AC$5<=IF($N24="",$L$1,$N24),WEEKDAY(AC$5,2)<6,COUNTIF(휴일!$A$2:$A$2,AC$5)=0),2,IF(AND(ISNUMBER($K24),AC$5>=$K24,AC$5<=$L24,WEEKDAY(AC$5,2)<6,COUNTIF(휴일!$A$2:$A$2,AC$5)=0),1,"")) | AD24: =IF(AND(ISNUMBER($M24),AD$5>=$M24,AD$5<=IF($N24="",$L$1,$N24),WEEKDAY(AD$5,2)<6,COUNTIF(휴일!$A$2:$A$2,AD$5)=0),2,IF(AND(ISNUMBER($K24),AD$5>=$K24,AD$5<=$L24,WEEKDAY(AD$5,2)<6,COUNTIF(휴일!$A$2:$A$2,AD$5)=0),1,"")) | AE24: =IF(AND(ISNUMBER($M24),AE$5>=$M24,AE$5<=IF($N24="",$L$1,$N24),WEEKDAY(AE$5,2)<6,COUNTIF(휴일!$A$2:$A$2,AE$5)=0),2,IF(AND(ISNUMBER($K24),AE$5>=$K24,AE$5<=$L24,WEEKDAY(AE$5,2)<6,COUNTIF(휴일!$A$2:$A$2,AE$5)=0),1,"")) | AF24: 완료
F25: 3.03 낙하 복귀·벽 충돌 검증 | H25: 권오민 | I25: 김찬중 | J25: FR-01 4개 구역 이동 및 낙하 복귀 재현 | K25: 46303 | L25: 46303 | M25: 46303 | N25: 46303 | O25: =IF(OR(K25="",L25=""),"",IF(L25<K25,"날짜 확인",NETWORKDAYS(K25,L25,휴일!$A$2:$A$2))) -> 1 | P25: =IF(OR(M25="",N25=""),"",IF(N25<M25,"날짜 확인",NETWORKDAYS(M25,N25,휴일!$A$2:$A$2))) -> 1 | Q25: =IF(O25="","",IF($L$1<K25,0,NETWORKDAYS(K25,MIN($L$1,L25),휴일!$A$2:$A$2))) -> 1 | R25: =IF(M25="","",IF($L$1<M25,0,NETWORKDAYS(M25,IF(N25="",$L$1,MIN($L$1,N25)),휴일!$A$2:$A$2))) -> 1 | S25: =IF(O25="","",IF(O25=0,0,Q25/O25)) -> 1 | T25: =IF(OR(AND(AG25<>"",OR(NOT(ISNUMBER(AG25)),AG25<=0)),AND(AH25<>"",OR(NOT(ISNUMBER(AH25)),AH25<0)),AND(ISNUMBER(AG25),ISNUMBER(AH25),AH25>AG25)),"수량 확인",IF(AF25="완료",1,IF(AF25="미착수",0,IF(AND(ISNUMBER(AG25),ISNUMBER(AH25)),AH25/AG25,"")))) -> 1 | U25: =IF(T25="","",T25) -> 1 | V25: =IF(OR(U25="",S25=""),"",U25-S25) -> 0 | W25: =IF(AND(ISNUMBER($M25),W$5>=$M25,W$5<=IF($N25="",$L$1,$N25),WEEKDAY(W$5,2)<6,COUNTIF(휴일!$A$2:$A$2,W$5)=0),2,IF(AND(ISNUMBER($K25),W$5>=$K25,W$5<=$L25,WEEKDAY(W$5,2)<6,COUNTIF(휴일!$A$2:$A$2,W$5)=0),1,"")) | X25: =IF(AND(ISNUMBER($M25),X$5>=$M25,X$5<=IF($N25="",$L$1,$N25),WEEKDAY(X$5,2)<6,COUNTIF(휴일!$A$2:$A$2,X$5)=0),2,IF(AND(ISNUMBER($K25),X$5>=$K25,X$5<=$L25,WEEKDAY(X$5,2)<6,COUNTIF(휴일!$A$2:$A$2,X$5)=0),1,"")) | Y25: =IF(AND(ISNUMBER($M25),Y$5>=$M25,Y$5<=IF($N25="",$L$1,$N25),WEEKDAY(Y$5,2)<6,COUNTIF(휴일!$A$2:$A$2,Y$5)=0),2,IF(AND(ISNUMBER($K25),Y$5>=$K25,Y$5<=$L25,WEEKDAY(Y$5,2)<6,COUNTIF(휴일!$A$2:$A$2,Y$5)=0),1,"")) -> 2 | Z25: =IF(AND(ISNUMBER($M25),Z$5>=$M25,Z$5<=IF($N25="",$L$1,$N25),WEEKDAY(Z$5,2)<6,COUNTIF(휴일!$A$2:$A$2,Z$5)=0),2,IF(AND(ISNUMBER($K25),Z$5>=$K25,Z$5<=$L25,WEEKDAY(Z$5,2)<6,COUNTIF(휴일!$A$2:$A$2,Z$5)=0),1,"")) | AA25: =IF(AND(ISNUMBER($M25),AA$5>=$M25,AA$5<=IF($N25="",$L$1,$N25),WEEKDAY(AA$5,2)<6,COUNTIF(휴일!$A$2:$A$2,AA$5)=0),2,IF(AND(ISNUMBER($K25),AA$5>=$K25,AA$5<=$L25,WEEKDAY(AA$5,2)<6,COUNTIF(휴일!$A$2:$A$2,AA$5)=0),1,"")) | AB25: =IF(AND(ISNUMBER($M25),AB$5>=$M25,AB$5<=IF($N25="",$L$1,$N25),WEEKDAY(AB$5,2)<6,COUNTIF(휴일!$A$2:$A$2,AB$5)=0),2,IF(AND(ISNUMBER($K25),AB$5>=$K25,AB$5<=$L25,WEEKDAY(AB$5,2)<6,COUNTIF(휴일!$A$2:$A$2,AB$5)=0),1,"")) | AC25: =IF(AND(ISNUMBER($M25),AC$5>=$M25,AC$5<=IF($N25="",$L$1,$N25),WEEKDAY(AC$5,2)<6,COUNTIF(휴일!$A$2:$A$2,AC$5)=0),2,IF(AND(ISNUMBER($K25),AC$5>=$K25,AC$5<=$L25,WEEKDAY(AC$5,2)<6,COUNTIF(휴일!$A$2:$A$2,AC$5)=0),1,"")) | AD25: =IF(AND(ISNUMBER($M25),AD$5>=$M25,AD$5<=IF($N25="",$L$1,$N25),WEEKDAY(AD$5,2)<6,COUNTIF(휴일!$A$2:$A$2,AD$5)=0),2,IF(AND(ISNUMBER($K25),AD$5>=$K25,AD$5<=$L25,WEEKDAY(AD$5,2)<6,COUNTIF(휴일!$A$2:$A$2,AD$5)=0),1,"")) | AE25: =IF(AND(ISNUMBER($M25),AE$5>=$M25,AE$5<=IF($N25="",$L$1,$N25),WEEKDAY(AE$5,2)<6,COUNTIF(휴일!$A$2:$A$2,AE$5)=0),2,IF(AND(ISNUMBER($K25),AE$5>=$K25,AE$5<=$L25,WEEKDAY(AE$5,2)<6,COUNTIF(휴일!$A$2:$A$2,AE$5)=0),1,"")) | AF25: 완료
